Workbook

Sheet 자재판매가산출
B2: 자재 판매가 산출 — 태성정밀 공급
B3: =" 적용 환율: "&설정!$C$8&" · USD "&TEXT(설정!$C$11,"#,##0.00")&" · CNY "&TEXT(설정!$C$12,"#,##0.00")&" · 부대비용 "&TEXT(설정!$C$17,"0.0%")&" · "&설정!$C$19&" "&TEXT(설정!$C$18,"0.0%")
B5: 품목 | C5: 품목코드 | D5: 통화 | E5: 외화 단가 | F5: 수량 | G5: 원화 환산 | H5: 입고원가 | I5: 이윤율 | J5: 적용 이윤율 | K5: 판매단가 | L5: 개당 마진 | M5: 마진율 | N5: 판매 합계 | O5: 원가 합계
C6: 710232.0 | D6: USD | E6: 8.5 | F6: 300 | G6: =IF(N($E6)=0,"",$E6*IF($D6="USD",설정!$C$11,IF($D6="CNY",설정!$C$12,1))) | H6: =IF($G6="","",$G6*(1+설정!$C$17)) | J6: =IF($G6="","",IF($I6="",설정!$C$18,$I6)) | K6: =IF($H6="","",IFERROR(IF(설정!$C$20<=1,ROUND(IF(설정!$C$19="판매가 마진",$H6/(1-$J6),$H6*(1+$J6)),0),CEILING(IF(설정!$C$19="판매가 마진",$H6/(1-$J6),$H6*(1+$J6)),설정!$C$20)),0)) | L6: =IF($K6="","",$K6-$H6) | M6: =IF(N($K6)=0,"",$L6/$K6) | N6: =IF($K6="","",$K6*$F6) | O6: =IF($H6="","",$H6*$F6)
C7: 710232.BN | D7: USD | E7: 9.3 | F7: 314 | G7: =IF(N($E7)=0,"",$E7*IF($D7="USD",설정!$C$11,IF($D7="CNY",설정!$C$12,1))) | H7: =IF($G7="","",$G7*(1+설정!$C$17)) | J7: =IF($G7="","",IF($I7="",설정!$C$18,$I7)) | K7: =IF($H7="","",IFERROR(IF(설정!$C$20<=1,ROUND(IF(설정!$C$19="판매가 마진",$H7/(1-$J7),$H7*(1+$J7)),0),CEILING(IF(설정!$C$19="판매가 마진",$H7/(1-$J7),$H7*(1+$J7)),설정!$C$20)),0)) | L7: =IF($K7="","",$K7-$H7) | M7: =IF(N($K7)=0,"",$L7/$K7) | N7: =IF($K7="","",$K7*$F7) | O7: =IF($H7="","",$H7*$F7)
G8: =IF(N($E8)=0,"",$E8*IF($D8="USD",설정!$C$11,IF($D8="CNY",설정!$C$12,1))) | H8: =IF($G8="","",$G8*(1+설정!$C$17)) | J8: =IF($G8="","",IF($I8="",설정!$C$18,$I8)) | K8: =IF($H8="","",IFERROR(IF(설정!$C$20<=1,ROUND(IF(설정!$C$19="판매가 마진",$H8/(1-$J8),$H8*(1+$J8)),0),CEILING(IF(설정!$C$19="판매가 마진",$H8/(1-$J8),$H8*(1+$J8)),설정!$C$20)),0)) | L8: =IF($K8="","",$K8-$H8) | M8: =IF(N($K8)=0,"",$L8/$K8) | N8: =IF($K8="","",$K8*$F8) | O8: =IF($H8="","",$H8*$F8)
G9: =IF(N($E9)=0,"",$E9*IF($D9="USD",설정!$C$11,IF($D9="CNY",설정!$C$12,1))) | H9: =IF($G9="","",$G9*(1+설정!$C$17)) | J9: =IF($G9="","",IF($I9="",설정!$C$18,$I9)) | K9: =IF($H9="","",IFERROR(IF(설정!$C$20<=1,ROUND(IF(설정!$C$19="판매가 마진",$H9/(1-$J9),$H9*(1+$J9)),0),CEILING(IF(설정!$C$19="판매가 마진",$H9/(1-$J9),$H9*(1+$J9)),설정!$C$20)),0)) | L9: =IF($K9="","",$K9-$H9) | M9: =IF(N($K9)=0,"",$L9/$K9) | N9: =IF($K9="","",$K9*$F9) | O9: =IF($H9="","",$H9*$F9)
G10: =IF(N($E10)=0,"",$E10*IF($D10="USD",설정!$C$11,IF($D10="CNY",설정!$C$12,1))) | H10: =IF($G10="","",$G10*(1+설정!$C$17)) | J10: =IF($G10="","",IF($I10="",설정!$C$18,$I10)) | K10: =IF($H10="","",IFERROR(IF(설정!$C$20<=1,ROUND(IF(설정!$C$19="판매가 마진",$H10/(1-$J10),$H10*(1+$J10)),0),CEILING(IF(설정!$C$19="판매가 마진",$H10/(1-$J10),$H10*(1+$J10)),설정!$C$20)),0)) | L10: =IF($K10="","",$K10-$H10) | M10: =IF(N($K10)=0,"",$L10/$K10) | N10: =IF($K10="","",$K10*$F10) | O10: =IF($H10="","",$H10*$F10)
G11: =IF(N($E11)=0,"",$E11*IF($D11="USD",설정!$C$11,IF($D11="CNY",설정!$C$12,1))) | H11: =IF($G11="","",$G11*(1+설정!$C$17)) | J11: =IF($G11="","",IF($I11="",설정!$C$18,$I11)) | K11: =IF($H11="","",IFERROR(IF(설정!$C$20<=1,ROUND(IF(설정!$C$19="판매가 마진",$H11/(1-$J11),$H11*(1+$J11)),0),CEILING(IF(설정!$C$19="판매가 마진",$H11/(1-$J11),$H11*(1+$J11)),설정!$C$20)),0)) | L11: =IF($K11="","",$K11-$H11) | M11: =IF(N($K11)=0,"",$L11/$K11) | N11: =IF($K11="","",$K11*$F11) | O11: =IF($H11="","",$H11*$F11)
G12: =IF(N($E12)=0,"",$E12*IF($D12="USD",설정!$C$11,IF($D12="CNY",설정!$C$12,1))) | H12: =IF($G12="","",$G12*(1+설정!$C$17)) | J12: =IF($G12="","",IF($I12="",설정!$C$18,$I12)) | K12: =IF($H12="","",IFERROR(IF(설정!$C$20<=1,ROUND(IF(설정!$C$19="판매가 마진",$H12/(1-$J12),$H12*(1+$J12)),0),CEILING(IF(설정!$C$19="판매가 마진",$H12/(1-$J12),$H12*(1+$J12)),설정!$C$20)),0)) | L12: =IF($K12="","",$K12-$H12) | M12: =IF(N($K12)=0,"",$L12/$K12) | N12: =IF($K12="","",$K12*$F12) | O12: =IF($H12="","",$H12*$F12)
G13: =IF(N($E13)=0,"",$E13*IF($D13="USD",설정!$C$11,IF($D13="CNY",설정!$C$12,1))) | H13: =IF($G13="","",$G13*(1+설정!$C$17)) | J13: =IF($G13="","",IF($I13="",설정!$C$18,$I13)) | K13: =IF($H13="","",IFERROR(IF(설정!$C$20<=1,ROUND(IF(설정!$C$19="판매가 마진",$H13/(1-$J13),$H13*(1+$J13)),0),CEILING(IF(설정!$C$19="판매가 마진",$H13/(1-$J13),$H13*(1+$J13)),설정!$C$20)),0)) | L13: =IF($K13="","",$K13-$H13) | M13: =IF(N($K13)=0,"",$L13/$K13) | N13: =IF($K13="","",$K13*$F13) | O13: =IF($H13="","",$H13*$F13)
G14: =IF(N($E14)=0,"",$E14*IF($D14="USD",설정!$C$11,IF($D14="CNY",설정!$C$12,1))) | H14: =IF($G14="","",$G14*(1+설정!$C$17)) | J14: =IF($G14="","",IF($I14="",설정!$C$18,$I14)) | K14: =IF($H14="","",IFERROR(IF(설정!$C$20<=1,ROUND(IF(설정!$C$19="판매가 마진",$H14/(1-$J14),$H14*(1+$J14)),0),CEILING(IF(설정!$C$19="판매가 마진",$H14/(1-$J14),$H14*(1+$J14)),설정!$C$20)),0)) | L14: =IF($K14="","",$K14-$H14) | M14: =IF(N($K14)=0,"",$L14/$K14) | N14: =IF($K14="","",$K14*$F14) | O14: =IF($H14="","",$H14*$F14)
G15: =IF(N($E15)=0,"",$E15*IF($D15="USD",설정!$C$11,IF($D15="CNY",설정!$C$12,1))) | H15: =IF($G15="","",$G15*(1+설정!$C$17)) | J15: =IF($G15="","",IF($I15="",설정!$C$18,$I15)) | K15: =IF($H15="","",IFERROR(IF(설정!$C$20<=1,ROUND(IF(설정!$C$19="판매가 마진",$H15/(1-$J15),$H15*(1+$J15)),0),CEILING(IF(설정!$C$19="판매가 마진",$H15/(1-$J15),$H15*(1+$J15)),설정!$C$20)),0)) | L15: =IF($K15="","",$K15-$H15) | M15: =IF(N($K15)=0,"",$L15/$K15) | N15: =IF($K15="","",$K15*$F15) | O15: =IF($H15="","",$H15*$F15)
G16: =IF(N($E16)=0,"",$E16*IF($D16="USD",설정!$C$11,IF($D16="CNY",설정!$C$12,1))) | H16: =IF($G16="","",$G16*(1+설정!$C$17)) | J16: =IF($G16="","",IF($I16="",설정!$C$18,$I16)) | K16: =IF($H16="","",IFERROR(IF(설정!$C$20<=1,ROUND(IF(설정!$C$19="판매가 마진",$H16/(1-$J16),$H16*(1+$J16)),0),CEILING(IF(설정!$C$19="판매가 마진",$H16/(1-$J16),$H16*(1+$J16)),설정!$C$20)),0)) | L16: =IF($K16="","",$K16-$H16) | M16: =IF(N($K16)=0,"",$L16/$K16) | N16: =IF($K16="","",$K16*$F16) | O16: =IF($H16="","",$H16*$F16)
G17: =IF(N($E17)=0,"",$E17*IF($D17="USD",설정!$C$11,IF($D17="CNY",설정!$C$12,1))) | H17: =IF($G17="","",$G17*(1+설정!$C$17)) | J17: =IF($G17="","",IF($I17="",설정!$C$18,$I17)) | K17: =IF($H17="","",IFERROR(IF(설정!$C$20<=1,ROUND(IF(설정!$C$19="판매가 마진",$H17/(1-$J17),$H17*(1+$J17)),0),CEILING(IF(설정!$C$19="판매가 마진",$H17/(1-$J17),$H17*(1+$J17)),설정!$C$20)),0)) | L17: =IF($K17="","",$K17-$H17) | M17: =IF(N($K17)=0,"",$L17/$K17) | N17: =IF($K17="","",$K17*$F17) | O17: =IF($H17="","",$H17*$F17)
G18: =IF(N($E18)=0,"",$E18*IF($D18="USD",설정!$C$11,IF($D18="CNY",설정!$C$12,1))) | H18: =IF($G18="","",$G18*(1+설정!$C$17)) | J18: =IF($G18="","",IF($I18="",설정!$C$18,$I18)) | K18: =IF($H18="","",IFERROR(IF(설정!$C$20<=1,ROUND(IF(설정!$C$19="판매가 마진",$H18/(1-$J18),$H18*(1+$J18)),0),CEILING(IF(설정!$C$19="판매가 마진",$H18/(1-$J18),$H18*(1+$J18)),설정!$C$20)),0)) | L18: =IF($K18="","",$K18-$H18) | M18: =IF(N($K18)=0,"",$L18/$K18) | N18: =IF($K18="","",$K18*$F18) | O18: =IF($H18="","",$H18*$F18)
G19: =IF(N($E19)=0,"",$E19*IF($D19="USD",설정!$C$11,IF($D19="CNY",설정!$C$12,1))) | H19: =IF($G19="","",$G19*(1+설정!$C$17)) | J19: =IF($G19="","",IF($I19="",설정!$C$18,$I19)) | K19: =IF($H19="","",IFERROR(IF(설정!$C$20<=1,ROUND(IF(설정!$C$19="판매가 마진",$H19/(1-$J19),$H19*(1+$J19)),0),CEILING(IF(설정!$C$19="판매가 마진",$H19/(1-$J19),$H19*(1+$J19)),설정!$C$20)),0)) | L19: =IF($K19="","",$K19-$H19) | M19: =IF(N($K19)=0,"",$L19/$K19) | N19: =IF($K19="","",$K19*$F19) | O19: =IF($H19="","",$H19*$F19)
... G24: =IF(N($E24)=0,"",$E24*IF($D24="USD",설정!$C$11,IF($D24="CNY",설정!$C$12,1))) | H24: =IF($G24="","",$G24*(1+설정!$C$17)) | J24: =IF($G24="","",IF($I24="",설정!$C$18,$I24)) | K24: =IF($H24="","",IFERROR(IF(설정!$C$20<=1,ROUND(IF(설정!$C$19="판매가 마진",$H24/(1-$J24),$H24*(1+$J24)),0),CEILING(IF(설정!$C$19="판매가 마진",$H24/(1-$J24),$H24*(1+$J24)),설정!$C$20)),0)) | L24: =IF($K24="","",$K24-$H24) | M24: =IF(N($K24)=0,"",$L24/$K24) | N24: =IF($K24="","",$K24*$F24) | O24: =IF($H24="","",$H24*$F24)
B25: 합계 | F25: =SUM(F6:F24) | L25: =SUM(L6:L24) | M25: =IFERROR(SUM(L6:L24)/SUM(N6:N24),0) | N25: =SUM(N6:N24) | O25: =SUM(O6:O24)
B27: 파란 글씨 칸(A~D, G)만 입력하세요. 나머지는 수식입니다.
B28: G열 이윤율을 비워 두면 설정 시트의 기본 이윤율이 적용됩니다.
B29: 샘플 6개 품목은 형식을 보여주기 위한 예시입니다. 실제 품목으로 교체하세요.
B30: 표시 금액은 모두 부가세 별도, 태성정밀 공급가 기준입니다.

Sheet 상품판매가산출
B2: 상품 판매가 산출 — 수입품 · 국내구매품 유통
B3: ="매입원가 → 판관비 "&TEXT(설정!$C$24,"0.0%")&" → BEP 가격 → 영업이익 "&TEXT(설정!$C$25,"0.0%")&" → 기준 유통가 → (영업) 최종 유통가 · "&설정!$C$26&" 방식"&" · 부대비용 수입 "&TEXT(설정!$C$17,"0.0%")&" / 에이전트 "&TEXT(설정!$C$29,"0.0%")&" / 국내 "&TEXT(설정!$C$23,"0.0%")
B5: 상품 | C5: 품목코드 | D5: 구분 | E5: 통화 | F5: 외화 단가 | G5: 원화 매입단가 | H5: 수량 | I5: 매입원가 /개 | J5: 판관비율 | K5: 영업이익률 | L5: BEP 가격 | M5: 기준 유통가 | N5: 최종 유통가 (영업 입력) | O5: 적용가 | P5: 판관비 /개 | Q5: 영업이익 /개 | R5: 영업이익률 (실제) | S5: 기준가 대비 | T5: BEP 대비 | U5: 매출 합계 | V5: 영업이익 합계 | W5: 소비자 마진율 | X5: 소비자 판매가
B6: 사각 원홀세면수전 크롬 | D6: 국내 | E6: KRW | G6: 29500 | H6: 300 | I6: =IF($D6="","",IF(OR($E6="USD",$E6="CNY"),IF(N($F6)=0,"",$F6*IF($E6="USD",설정!$C$11,설정!$C$12)*(1+IF($D6="수입",설정!$C$17,설정!$C$23))),IF(N($G6)=0,"",$G6*(1+IF($D6="수입",설정!$C$29,설정!$C$23))))) | L6: =IF($I6="","",IFERROR(IF(설정!$C$26="원가 가산",$I6*(1+IF($J6="",설정!$C$24,$J6)),$I6/(1-IF($J6="",설정!$C$24,$J6))),0)) | M6: =IF($I6="","",IFERROR(IF(설정!$C$27<=1,ROUND(IF(설정!$C$26="원가 가산",$L6*(1+IF($K6="",설정!$C$25,$K6)),$I6/(1-IF($J6="",설정!$C$24,$J6)-IF($K6="",설정!$C$25,$K6))),0),CEILING(IF(설정!$C$26="원가 가산",$L6*(1+IF($K6="",설정!$C$25,$K6)),$I6/(1-IF($J6="",설정!$C$24,$J6)-IF($K6="",설정!$C$25,$K6))),설정!$C$27)),0)) | O6: =IF($M6="","",IF($N6="",$M6,$N6)) | P6: =IF($O6="","",IF(설정!$C$26="원가 가산",$I6*IF($J6="",설정!$C$24,$J6),$O6*IF($J6="",설정!$C$24,$J6))) | Q6: =IF($O6="","",$O6-$I6-$P6) | R6: =IF(N($O6)=0,"",$Q6/$O6) | S6: =IF(N($M6)=0,"",$O6/$M6-1) | T6: =IF(N($L6)=0,"",$O6/$L6-1) | U6: =IF($O6="","",$O6*$H6) | V6: =IF($Q6="","",$Q6*$H6) | X6: =IF($O6="","",IFERROR(IF(설정!$C$27<=1,ROUND(IF(설정!$C$26="원가 가산",$O6*(1+IF($W6="",설정!$C$28,$W6)),$O6/(1-IF($W6="",설정!$C$28,$W6))),0),CEILING(IF(설정!$C$26="원가 가산",$O6*(1+IF($W6="",설정!$C$28,$W6)),$O6/(1-IF($W6="",설정!$C$28,$W6))),설정!$C$27)),0))
B7: 사각 원홀세면수전 브러시니켈 | D7: 국내 | E7: KRW | H7: 300 | I7: =IF($D7="","",IF(OR($E7="USD",$E7="CNY"),IF(N($F7)=0,"",$F7*IF($E7="USD",설정!$C$11,설정!$C$12)*(1+IF($D7="수입",설정!$C$17,설정!$C$23))),IF(N($G7)=0,"",$G7*(1+IF($D7="수입",설정!$C$29,설정!$C$23))))) | L7: =IF($I7="","",IFERROR(IF(설정!$C$26="원가 가산",$I7*(1+IF($J7="",설정!$C$24,$J7)),$I7/(1-IF($J7="",설정!$C$24,$J7))),0)) | M7: =IF($I7="","",IFERROR(IF(설정!$C$27<=1,ROUND(IF(설정!$C$26="원가 가산",$L7*(1+IF($K7="",설정!$C$25,$K7)),$I7/(1-IF($J7="",설정!$C$24,$J7)-IF($K7="",설정!$C$25,$K7))),0),CEILING(IF(설정!$C$26="원가 가산",$L7*(1+IF($K7="",설정!$C$25,$K7)),$I7/(1-IF($J7="",설정!$C$24,$J7)-IF($K7="",설정!$C$25,$K7))),설정!$C$27)),0)) | O7: =IF($M7="","",IF($N7="",$M7,$N7)) | P7: =IF($O7="","",IF(설정!$C$26="원가 가산",$I7*IF($J7="",설정!$C$24,$J7),$O7*IF($J7="",설정!$C$24,$J7))) | Q7: =IF($O7="","",$O7-$I7-$P7) | R7: =IF(N($O7)=0,"",$Q7/$O7) | S7: =IF(N($M7)=0,"",$O7/$M7-1) | T7: =IF(N($L7)=0,"",$O7/$L7-1) | U7: =IF($O7="","",$O7*$H7) | V7: =IF($Q7="","",$Q7*$H7) | X7: =IF($O7="","",IFERROR(IF(설정!$C$27<=1,ROUND(IF(설정!$C$26="원가 가산",$O7*(1+IF($W7="",설정!$C$28,$W7)),$O7/(1-IF($W7="",설정!$C$28,$W7))),0),CEILING(IF(설정!$C$26="원가 가산",$O7*(1+IF($W7="",설정!$C$28,$W7)),$O7/(1-IF($W7="",설정!$C$28,$W7))),설정!$C$27)),0))
B8: 사각 욕조수전 크롬 | D8: 국내 | E8: KRW | H8: 300 | I8: =IF($D8="","",IF(OR($E8="USD",$E8="CNY"),IF(N($F8)=0,"",$F8*IF($E8="USD",설정!$C$11,설정!$C$12)*(1+IF($D8="수입",설정!$C$17,설정!$C$23))),IF(N($G8)=0,"",$G8*(1+IF($D8="수입",설정!$C$29,설정!$C$23))))) | L8: =IF($I8="","",IFERROR(IF(설정!$C$26="원가 가산",$I8*(1+IF($J8="",설정!$C$24,$J8)),$I8/(1-IF($J8="",설정!$C$24,$J8))),0)) | M8: =IF($I8="","",IFERROR(IF(설정!$C$27<=1,ROUND(IF(설정!$C$26="원가 가산",$L8*(1+IF($K8="",설정!$C$25,$K8)),$I8/(1-IF($J8="",설정!$C$24,$J8)-IF($K8="",설정!$C$25,$K8))),0),CEILING(IF(설정!$C$26="원가 가산",$L8*(1+IF($K8="",설정!$C$25,$K8)),$I8/(1-IF($J8="",설정!$C$24,$J8)-IF($K8="",설정!$C$25,$K8))),설정!$C$27)),0)) | O8: =IF($M8="","",IF($N8="",$M8,$N8)) | P8: =IF($O8="","",IF(설정!$C$26="원가 가산",$I8*IF($J8="",설정!$C$24,$J8),$O8*IF($J8="",설정!$C$24,$J8))) | Q8: =IF($O8="","",$O8-$I8-$P8) | R8: =IF(N($O8)=0,"",$Q8/$O8) | S8: =IF(N($M8)=0,"",$O8/$M8-1) | T8: =IF(N($L8)=0,"",$O8/$L8-1) | U8: =IF($O8="","",$O8*$H8) | V8: =IF($Q8="","",$Q8*$H8) | X8: =IF($O8="","",IFERROR(IF(설정!$C$27<=1,ROUND(IF(설정!$C$26="원가 가산",$O8*(1+IF($W8="",설정!$C$28,$W8)),$O8/(1-IF($W8="",설정!$C$28,$W8))),0),CEILING(IF(설정!$C$26="원가 가산",$O8*(1+IF($W8="",설정!$C$28,$W8)),$O8/(1-IF($W8="",설정!$C$28,$W8))),설정!$C$27)),0))
B9: 사각 욕조수전 브러시니켈 | D9: 국내 | E9: KRW | H9: 300 | I9: =IF($D9="","",IF(OR($E9="USD",$E9="CNY"),IF(N($F9)=0,"",$F9*IF($E9="USD",설정!$C$11,설정!$C$12)*(1+IF($D9="수입",설정!$C$17,설정!$C$23))),IF(N($G9)=0,"",$G9*(1+IF($D9="수입",설정!$C$29,설정!$C$23))))) | L9: =IF($I9="","",IFERROR(IF(설정!$C$26="원가 가산",$I9*(1+IF($J9="",설정!$C$24,$J9)),$I9/(1-IF($J9="",설정!$C$24,$J9))),0)) | M9: =IF($I9="","",IFERROR(IF(설정!$C$27<=1,ROUND(IF(설정!$C$26="원가 가산",$L9*(1+IF($K9="",설정!$C$25,$K9)),$I9/(1-IF($J9="",설정!$C$24,$J9)-IF($K9="",설정!$C$25,$K9))),0),CEILING(IF(설정!$C$26="원가 가산",$L9*(1+IF($K9="",설정!$C$25,$K9)),$I9/(1-IF($J9="",설정!$C$24,$J9)-IF($K9="",설정!$C$25,$K9))),설정!$C$27)),0)) | O9: =IF($M9="","",IF($N9="",$M9,$N9)) | P9: =IF($O9="","",IF(설정!$C$26="원가 가산",$I9*IF($J9="",설정!$C$24,$J9),$O9*IF($J9="",설정!$C$24,$J9))) | Q9: =IF($O9="","",$O9-$I9-$P9) | R9: =IF(N($O9)=0,"",$Q9/$O9) | S9: =IF(N($M9)=0,"",$O9/$M9-1) | T9: =IF(N($L9)=0,"",$O9/$L9-1) | U9: =IF($O9="","",$O9*$H9) | V9: =IF($Q9="","",$Q9*$H9) | X9: =IF($O9="","",IFERROR(IF(설정!$C$27<=1,ROUND(IF(설정!$C$26="원가 가산",$O9*(1+IF($W9="",설정!$C$28,$W9)),$O9/(1-IF($W9="",설정!$C$28,$W9))),0),CEILING(IF(설정!$C$26="원가 가산",$O9*(1+IF($W9="",설정!$C$28,$W9)),$O9/(1-IF($W9="",설정!$C$28,$W9))),설정!$C$27)),0))
B10: 원형 원홀세면수전 크롬 | D10: 국내 | E10: KRW | H10: 300 | I10: =IF($D10="","",IF(OR($E10="USD",$E10="CNY"),IF(N($F10)=0,"",$F10*IF($E10="USD",설정!$C$11,설정!$C$12)*(1+IF($D10="수입",설정!$C$17,설정!$C$23))),IF(N($G10)=0,"",$G10*(1+IF($D10="수입",설정!$C$29,설정!$C$23))))) | L10: =IF($I10="","",IFERROR(IF(설정!$C$26="원가 가산",$I10*(1+IF($J10="",설정!$C$24,$J10)),$I10/(1-IF($J10="",설정!$C$24,$J10))),0)) | M10: =IF($I10="","",IFERROR(IF(설정!$C$27<=1,ROUND(IF(설정!$C$26="원가 가산",$L10*(1+IF($K10="",설정!$C$25,$K10)),$I10/(1-IF($J10="",설정!$C$24,$J10)-IF($K10="",설정!$C$25,$K10))),0),CEILING(IF(설정!$C$26="원가 가산",$L10*(1+IF($K10="",설정!$C$25,$K10)),$I10/(1-IF($J10="",설정!$C$24,$J10)-IF($K10="",설정!$C$25,$K10))),설정!$C$27)),0)) | O10: =IF($M10="","",IF($N10="",$M10,$N10)) | P10: =IF($O10="","",IF(설정!$C$26="원가 가산",$I10*IF($J10="",설정!$C$24,$J10),$O10*IF($J10="",설정!$C$24,$J10))) | Q10: =IF($O10="","",$O10-$I10-$P10) | R10: =IF(N($O10)=0,"",$Q10/$O10) | S10: =IF(N($M10)=0,"",$O10/$M10-1) | T10: =IF(N($L10)=0,"",$O10/$L10-1) | U10: =IF($O10="","",$O10*$H10) | V10: =IF($Q10="","",$Q10*$H10) | X10: =IF($O10="","",IFERROR(IF(설정!$C$27<=1,ROUND(IF(설정!$C$26="원가 가산",$O10*(1+IF($W10="",설정!$C$28,$W10)),$O10/(1-IF($W10="",설정!$C$28,$W10))),0),CEILING(IF(설정!$C$26="원가 가산",$O10*(1+IF($W10="",설정!$C$28,$W10)),$O10/(1-IF($W10="",설정!$C$28,$W10))),설정!$C$27)),0))
B11: 원홀 원홀세면수전 브러시니켈 | D11: 국내 | E11: KRW | H11: 300 | I11: =IF($D11="","",IF(OR($E11="USD",$E11="CNY"),IF(N($F11)=0,"",$F11*IF($E11="USD",설정!$C$11,설정!$C$12)*(1+IF($D11="수입",설정!$C$17,설정!$C$23))),IF(N($G11)=0,"",$G11*(1+IF($D11="수입",설정!$C$29,설정!$C$23))))) | L11: =IF($I11="","",IFERROR(IF(설정!$C$26="원가 가산",$I11*(1+IF($J11="",설정!$C$24,$J11)),$I11/(1-IF($J11="",설정!$C$24,$J11))),0)) | M11: =IF($I11="","",IFERROR(IF(설정!$C$27<=1,ROUND(IF(설정!$C$26="원가 가산",$L11*(1+IF($K11="",설정!$C$25,$K11)),$I11/(1-IF($J11="",설정!$C$24,$J11)-IF($K11="",설정!$C$25,$K11))),0),CEILING(IF(설정!$C$26="원가 가산",$L11*(1+IF($K11="",설정!$C$25,$K11)),$I11/(1-IF($J11="",설정!$C$24,$J11)-IF($K11="",설정!$C$25,$K11))),설정!$C$27)),0)) | O11: =IF($M11="","",IF($N11="",$M11,$N11)) | P11: =IF($O11="","",IF(설정!$C$26="원가 가산",$I11*IF($J11="",설정!$C$24,$J11),$O11*IF($J11="",설정!$C$24,$J11))) | Q11: =IF($O11="","",$O11-$I11-$P11) | R11: =IF(N($O11)=0,"",$Q11/$O11) | S11: =IF(N($M11)=0,"",$O11/$M11-1) | T11: =IF(N($L11)=0,"",$O11/$L11-1) | U11: =IF($O11="","",$O11*$H11) | V11: =IF($Q11="","",$Q11*$H11) | X11: =IF($O11="","",IFERROR(IF(설정!$C$27<=1,ROUND(IF(설정!$C$26="원가 가산",$O11*(1+IF($W11="",설정!$C$28,$W11)),$O11/(1-IF($W11="",설정!$C$28,$W11))),0),CEILING(IF(설정!$C$26="원가 가산",$O11*(1+IF($W11="",설정!$C$28,$W11)),$O11/(1-IF($W11="",설정!$C$28,$W11))),설정!$C$27)),0))
B12: 원형 욕조수전 크롬 | D12: 국내 | E12: KRW | H12: 300 | I12: =IF($D12="","",IF(OR($E12="USD",$E12="CNY"),IF(N($F12)=0,"",$F12*IF($E12="USD",설정!$C$11,설정!$C$12)*(1+IF($D12="수입",설정!$C$17,설정!$C$23))),IF(N($G12)=0,"",$G12*(1+IF($D12="수입",설정!$C$29,설정!$C$23))))) | L12: =IF($I12="","",IFERROR(IF(설정!$C$26="원가 가산",$I12*(1+IF($J12="",설정!$C$24,$J12)),$I12/(1-IF($J12="",설정!$C$24,$J12))),0)) | M12: =IF($I12="","",IFERROR(IF(설정!$C$27<=1,ROUND(IF(설정!$C$26="원가 가산",$L12*(1+IF($K12="",설정!$C$25,$K12)),$I12/(1-IF($J12="",설정!$C$24,$J12)-IF($K12="",설정!$C$25,$K12))),0),CEILING(IF(설정!$C$26="원가 가산",$L12*(1+IF($K12="",설정!$C$25,$K12)),$I12/(1-IF($J12="",설정!$C$24,$J12)-IF($K12="",설정!$C$25,$K12))),설정!$C$27)),0)) | O12: =IF($M12="","",IF($N12="",$M12,$N12)) | P12: =IF($O12="","",IF(설정!$C$26="원가 가산",$I12*IF($J12="",설정!$C$24,$J12),$O12*IF($J12="",설정!$C$24,$J12))) | Q12: =IF($O12="","",$O12-$I12-$P12) | R12: =IF(N($O12)=0,"",$Q12/$O12) | S12: =IF(N($M12)=0,"",$O12/$M12-1) | T12: =IF(N($L12)=0,"",$O12/$L12-1) | U12: =IF($O12="","",$O12*$H12) | V12: =IF($Q12="","",$Q12*$H12) | X12: =IF($O12="","",IFERROR(IF(설정!$C$27<=1,ROUND(IF(설정!$C$26="원가 가산",$O12*(1+IF($W12="",설정!$C$28,$W12)),$O12/(1-IF($W12="",설정!$C$28,$W12))),0),CEILING(IF(설정!$C$26="원가 가산",$O12*(1+IF($W12="",설정!$C$28,$W12)),$O12/(1-IF($W12="",설정!$C$28,$W12))),설정!$C$27)),0))
B13: 원형 욕조수전 브러시니켈 | D13: 수입 | E13: KRW | H13: 300 | I13: =IF($D13="","",IF(OR($E13="USD",$E13="CNY"),IF(N($F13)=0,"",$F13*IF($E13="USD",설정!$C$11,설정!$C$12)*(1+IF($D13="수입",설정!$C$17,설정!$C$23))),IF(N($G13)=0,"",$G13*(1+IF($D13="수입",설정!$C$29,설정!$C$23))))) | L13: =IF($I13="","",IFERROR(IF(설정!$C$26="원가 가산",$I13*(1+IF($J13="",설정!$C$24,$J13)),$I13/(1-IF($J13="",설정!$C$24,$J13))),0)) | M13: =IF($I13="","",IFERROR(IF(설정!$C$27<=1,ROUND(IF(설정!$C$26="원가 가산",$L13*(1+IF($K13="",설정!$C$25,$K13)),$I13/(1-IF($J13="",설정!$C$24,$J13)-IF($K13="",설정!$C$25,$K13))),0),CEILING(IF(설정!$C$26="원가 가산",$L13*(1+IF($K13="",설정!$C$25,$K13)),$I13/(1-IF($J13="",설정!$C$24,$J13)-IF($K13="",설정!$C$25,$K13))),설정!$C$27)),0)) | O13: =IF($M13="","",IF($N13="",$M13,$N13)) | P13: =IF($O13="","",IF(설정!$C$26="원가 가산",$I13*IF($J13="",설정!$C$24,$J13),$O13*IF($J13="",설정!$C$24,$J13))) | Q13: =IF($O13="","",$O13-$I13-$P13) | R13: =IF(N($O13)=0,"",$Q13/$O13) | S13: =IF(N($M13)=0,"",$O13/$M13-1) | T13: =IF(N($L13)=0,"",$O13/$L13-1) | U13: =IF($O13="","",$O13*$H13) | V13: =IF($Q13="","",$Q13*$H13) | X13: =IF($O13="","",IFERROR(IF(설정!$C$27<=1,ROUND(IF(설정!$C$26="원가 가산",$O13*(1+IF($W13="",설정!$C$28,$W13)),$O13/(1-IF($W13="",설정!$C$28,$W13))),0),CEILING(IF(설정!$C$26="원가 가산",$O13*(1+IF($W13="",설정!$C$28,$W13)),$O13/(1-IF($W13="",설정!$C$28,$W13))),설정!$C$27)),0))
I14: =IF($D14="","",IF(OR($E14="USD",$E14="CNY"),IF(N($F14)=0,"",$F14*IF($E14="USD",설정!$C$11,설정!$C$12)*(1+IF($D14="수입",설정!$C$17,설정!$C$23))),IF(N($G14)=0,"",$G14*(1+IF($D14="수입",설정!$C$29,설정!$C$23))))) | L14: =IF($I14="","",IFERROR(IF(설정!$C$26="원가 가산",$I14*(1+IF($J14="",설정!$C$24,$J14)),$I14/(1-IF($J14="",설정!$C$24,$J14))),0)) | M14: =IF($I14="","",IFERROR(IF(설정!$C$27<=1,ROUND(IF(설정!$C$26="원가 가산",$L14*(1+IF($K14="",설정!$C$25,$K14)),$I14/(1-IF($J14="",설정!$C$24,$J14)-IF($K14="",설정!$C$25,$K14))),0),CEILING(IF(설정!$C$26="원가 가산",$L14*(1+IF($K14="",설정!$C$25,$K14)),$I14/(1-IF($J14="",설정!$C$24,$J14)-IF($K14="",설정!$C$25,$K14))),설정!$C$27)),0)) | O14: =IF($M14="","",IF($N14="",$M14,$N14)) | P14: =IF($O14="","",IF(설정!$C$26="원가 가산",$I14*IF($J14="",설정!$C$24,$J14),$O14*IF($J14="",설정!$C$24,$J14))) | Q14: =IF($O14="","",$O14-$I14-$P14) | R14: =IF(N($O14)=0,"",$Q14/$O14) | S14: =IF(N($M14)=0,"",$O14/$M14-1) | T14: =IF(N($L14)=0,"",$O14/$L14-1) | U14: =IF($O14="","",$O14*$H14) | V14: =IF($Q14="","",$Q14*$H14) | X14: =IF($O14="","",IFERROR(IF(설정!$C$27<=1,ROUND(IF(설정!$C$26="원가 가산",$O14*(1+IF($W14="",설정!$C$28,$W14)),$O14/(1-IF($W14="",설정!$C$28,$W14))),0),CEILING(IF(설정!$C$26="원가 가산",$O14*(1+IF($W14="",설정!$C$28,$W14)),$O14/(1-IF($W14="",설정!$C$28,$W14))),설정!$C$27)),0))
I15: =IF($D15="","",IF(OR($E15="USD",$E15="CNY"),IF(N($F15)=0,"",$F15*IF($E15="USD",설정!$C$11,설정!$C$12)*(1+IF($D15="수입",설정!$C$17,설정!$C$23))),IF(N($G15)=0,"",$G15*(1+IF($D15="수입",설정!$C$29,설정!$C$23))))) | L15: =IF($I15="","",IFERROR(IF(설정!$C$26="원가 가산",$I15*(1+IF($J15="",설정!$C$24,$J15)),$I15/(1-IF($J15="",설정!$C$24,$J15))),0)) | M15: =IF($I15="","",IFERROR(IF(설정!$C$27<=1,ROUND(IF(설정!$C$26="원가 가산",$L15*(1+IF($K15="",설정!$C$25,$K15)),$I15/(1-IF($J15="",설정!$C$24,$J15)-IF($K15="",설정!$C$25,$K15))),0),CEILING(IF(설정!$C$26="원가 가산",$L15*(1+IF($K15="",설정!$C$25,$K15)),$I15/(1-IF($J15="",설정!$C$24,$J15)-IF($K15="",설정!$C$25,$K15))),설정!$C$27)),0)) | O15: =IF($M15="","",IF($N15="",$M15,$N15)) | P15: =IF($O15="","",IF(설정!$C$26="원가 가산",$I15*IF($J15="",설정!$C$24,$J15),$O15*IF($J15="",설정!$C$24,$J15))) | Q15: =IF($O15="","",$O15-$I15-$P15) | R15: =IF(N($O15)=0,"",$Q15/$O15) | S15: =IF(N($M15)=0,"",$O15/$M15-1) | T15: =IF(N($L15)=0,"",$O15/$L15-1) | U15: =IF($O15="","",$O15*$H15) | V15: =IF($Q15="","",$Q15*$H15) | X15: =IF($O15="","",IFERROR(IF(설정!$C$27<=1,ROUND(IF(설정!$C$26="원가 가산",$O15*(1+IF($W15="",설정!$C$28,$W15)),$O15/(1-IF($W15="",설정!$C$28,$W15))),0),CEILING(IF(설정!$C$26="원가 가산",$O15*(1+IF($W15="",설정!$C$28,$W15)),$O15/(1-IF($W15="",설정!$C$28,$W15))),설정!$C$27)),0))
I16: =IF($D16="","",IF(OR($E16="USD",$E16="CNY"),IF(N($F16)=0,"",$F16*IF($E16="USD",설정!$C$11,설정!$C$12)*(1+IF($D16="수입",설정!$C$17,설정!$C$23))),IF(N($G16)=0,"",$G16*(1+IF($D16="수입",설정!$C$29,설정!$C$23))))) | L16: =IF($I16="","",IFERROR(IF(설정!$C$26="원가 가산",$I16*(1+IF($J16="",설정!$C$24,$J16)),$I16/(1-IF($J16="",설정!$C$24,$J16))),0)) | M16: =IF($I16="","",IFERROR(IF(설정!$C$27<=1,ROUND(IF(설정!$C$26="원가 가산",$L16*(1+IF($K16="",설정!$C$25,$K16)),$I16/(1-IF($J16="",설정!$C$24,$J16)-IF($K16="",설정!$C$25,$K16))),0),CEILING(IF(설정!$C$26="원가 가산",$L16*(1+IF($K16="",설정!$C$25,$K16)),$I16/(1-IF($J16="",설정!$C$24,$J16)-IF($K16="",설정!$C$25,$K16))),설정!$C$27)),0)) | O16: =IF($M16="","",IF($N16="",$M16,$N16)) | P16: =IF($O16="","",IF(설정!$C$26="원가 가산",$I16*IF($J16="",설정!$C$24,$J16),$O16*IF($J16="",설정!$C$24,$J16))) | Q16: =IF($O16="","",$O16-$I16-$P16) | R16: =IF(N($O16)=0,"",$Q16/$O16) | S16: =IF(N($M16)=0,"",$O16/$M16-1) | T16: =IF(N($L16)=0,"",$O16/$L16-1) | U16: =IF($O16="","",$O16*$H16) | V16: =IF($Q16="","",$Q16*$H16) | X16: =IF($O16="","",IFERROR(IF(설정!$C$27<=1,ROUND(IF(설정!$C$26="원가 가산",$O16*(1+IF($W16="",설정!$C$28,$W16)),$O16/(1-IF($W16="",설정!$C$28,$W16))),0),CEILING(IF(설정!$C$26="원가 가산",$O16*(1+IF($W16="",설정!$C$28,$W16)),$O16/(1-IF($W16="",설정!$C$28,$W16))),설정!$C$27)),0))
I17: =IF($D17="","",IF(OR($E17="USD",$E17="CNY"),IF(N($F17)=0,"",$F17*IF($E17="USD",설정!$C$11,설정!$C$12)*(1+IF($D17="수입",설정!$C$17,설정!$C$23))),IF(N($G17)=0,"",$G17*(1+IF($D17="수입",설정!$C$29,설정!$C$23))))) | L17: =IF($I17="","",IFERROR(IF(설정!$C$26="원가 가산",$I17*(1+IF($J17="",설정!$C$24,$J17)),$I17/(1-IF($J17="",설정!$C$24,$J17))),0)) | M17: =IF($I17="","",IFERROR(IF(설정!$C$27<=1,ROUND(IF(설정!$C$26="원가 가산",$L17*(1+IF($K17="",설정!$C$25,$K17)),$I17/(1-IF($J17="",설정!$C$24,$J17)-IF($K17="",설정!$C$25,$K17))),0),CEILING(IF(설정!$C$26="원가 가산",$L17*(1+IF($K17="",설정!$C$25,$K17)),$I17/(1-IF($J17="",설정!$C$24,$J17)-IF($K17="",설정!$C$25,$K17))),설정!$C$27)),0)) | O17: =IF($M17="","",IF($N17="",$M17,$N17)) | P17: =IF($O17="","",IF(설정!$C$26="원가 가산",$I17*IF($J17="",설정!$C$24,$J17),$O17*IF($J17="",설정!$C$24,$J17))) | Q17: =IF($O17="","",$O17-$I17-$P17) | R17: =IF(N($O17)=0,"",$Q17/$O17) | S17: =IF(N($M17)=0,"",$O17/$M17-1) | T17: =IF(N($L17)=0,"",$O17/$L17-1) | U17: =IF($O17="","",$O17*$H17) | V17: =IF($Q17="","",$Q17*$H17) | X17: =IF($O17="","",IFERROR(IF(설정!$C$27<=1,ROUND(IF(설정!$C$26="원가 가산",$O17*(1+IF($W17="",설정!$C$28,$W17)),$O17/(1-IF($W17="",설정!$C$28,$W17))),0),CEILING(IF(설정!$C$26="원가 가산",$O17*(1+IF($W17="",설정!$C$28,$W17)),$O17/(1-IF($W17="",설정!$C$28,$W17))),설정!$C$27)),0))
I18: =IF($D18="","",IF(OR($E18="USD",$E18="CNY"),IF(N($F18)=0,"",$F18*IF($E18="USD",설정!$C$11,설정!$C$12)*(1+IF($D18="수입",설정!$C$17,설정!$C$23))),IF(N($G18)=0,"",$G18*(1+IF($D18="수입",설정!$C$29,설정!$C$23))))) | L18: =IF($I18="","",IFERROR(IF(설정!$C$26="원가 가산",$I18*(1+IF($J18="",설정!$C$24,$J18)),$I18/(1-IF($J18="",설정!$C$24,$J18))),0)) | M18: =IF($I18="","",IFERROR(IF(설정!$C$27<=1,ROUND(IF(설정!$C$26="원가 가산",$L18*(1+IF($K18="",설정!$C$25,$K18)),$I18/(1-IF($J18="",설정!$C$24,$J18)-IF($K18="",설정!$C$25,$K18))),0),CEILING(IF(설정!$C$26="원가 가산",$L18*(1+IF($K18="",설정!$C$25,$K18)),$I18/(1-IF($J18="",설정!$C$24,$J18)-IF($K18="",설정!$C$25,$K18))),설정!$C$27)),0)) | O18: =IF($M18="","",IF($N18="",$M18,$N18)) | P18: =IF($O18="","",IF(설정!$C$26="원가 가산",$I18*IF($J18="",설정!$C$24,$J18),$O18*IF($J18="",설정!$C$24,$J18))) | Q18: =IF($O18="","",$O18-$I18-$P18) | R18: =IF(N($O18)=0,"",$Q18/$O18) | S18: =IF(N($M18)=0,"",$O18/$M18-1) | T18: =IF(N($L18)=0,"",$O18/$L18-1) | U18: =IF($O18="","",$O18*$H18) | V18: =IF($Q18="","",$Q18*$H18) | X18: =IF($O18="","",IFERROR(IF(설정!$C$27<=1,ROUND(IF(설정!$C$26="원가 가산",$O18*(1+IF($W18="",설정!$C$28,$W18)),$O18/(1-IF($W18="",설정!$C$28,$W18))),0),CEILING(IF(설정!$C$26="원가 가산",$O18*(1+IF($W18="",설정!$C$28,$W18)),$O18/(1-IF($W18="",설정!$C$28,$W18))),설정!$C$27)),0))
I19: =IF($D19="","",IF(OR($E19="USD",$E19="CNY"),IF(N($F19)=0,"",$F19*IF($E19="USD",설정!$C$11,설정!$C$12)*(1+IF($D19="수입",설정!$C$17,설정!$C$23))),IF(N($G19)=0,"",$G19*(1+IF($D19="수입",설정!$C$29,설정!$C$23))))) | L19: =IF($I19="","",IFERROR(IF(설정!$C$26="원가 가산",$I19*(1+IF($J19="",설정!$C$24,$J19)),$I19/(1-IF($J19="",설정!$C$24,$J19))),0)) | M19: =IF($I19="","",IFERROR(IF(설정!$C$27<=1,ROUND(IF(설정!$C$26="원가 가산",$L19*(1+IF($K19="",설정!$C$25,$K19)),$I19/(1-IF($J19="",설정!$C$24,$J19)-IF($K19="",설정!$C$25,$K19))),0),CEILING(IF(설정!$C$26="원가 가산",$L19*(1+IF($K19="",설정!$C$25,$K19)),$I19/(1-IF($J19="",설정!$C$24,$J19)-IF($K19="",설정!$C$25,$K19))),설정!$C$27)),0)) | O19: =IF($M19="","",IF($N19="",$M19,$N19)) | P19: =IF($O19="","",IF(설정!$C$26="원가 가산",$I19*IF($J19="",설정!$C$24,$J19),$O19*IF($J19="",설정!$C$24,$J19))) | Q19: =IF($O19="","",$O19-$I19-$P19) | R19: =IF(N($O19)=0,"",$Q19/$O19) | S19: =IF(N($M19)=0,"",$O19/$M19-1) | T19: =IF(N($L19)=0,"",$O19/$L19-1) | U19: =IF($O19="","",$O19*$H19) | V19: =IF($Q19="","",$Q19*$H19) | X19: =IF($O19="","",IFERROR(IF(설정!$C$27<=1,ROUND(IF(설정!$C$26="원가 가산",$O19*(1+IF($W19="",설정!$C$28,$W19)),$O19/(1-IF($W19="",설정!$C$28,$W19))),0),CEILING(IF(설정!$C$26="원가 가산",$O19*(1+IF($W19="",설정!$C$28,$W19)),$O19/(1-IF($W19="",설정!$C$28,$W19))),설정!$C$27)),0))
I20: =IF($D20="","",IF(OR($E20="USD",$E20="CNY"),IF(N($F20)=0,"",$F20*IF($E20="USD",설정!$C$11,설정!$C$12)*(1+IF($D20="수입",설정!$C$17,설정!$C$23))),IF(N($G20)=0,"",$G20*(1+IF($D20="수입",설정!$C$29,설정!$C$23))))) | L20: =IF($I20="","",IFERROR(IF(설정!$C$26="원가 가산",$I20*(1+IF($J20="",설정!$C$24,$J20)),$I20/(1-IF($J20="",설정!$C$24,$J20))),0)) | M20: =IF($I20="","",IFERROR(IF(설정!$C$27<=1,ROUND(IF(설정!$C$26="원가 가산",$L20*(1+IF($K20="",설정!$C$25,$K20)),$I20/(1-IF($J20="",설정!$C$24,$J20)-IF($K20="",설정!$C$25,$K20))),0),CEILING(IF(설정!$C$26="원가 가산",$L20*(1+IF($K20="",설정!$C$25,$K20)),$I20/(1-IF($J20="",설정!$C$24,$J20)-IF($K20="",설정!$C$25,$K20))),설정!$C$27)),0)) | O20: =IF($M20="","",IF($N20="",$M20,$N20)) | P20: =IF($O20="","",IF(설정!$C$26="원가 가산",$I20*IF($J20="",설정!$C$24,$J20),$O20*IF($J20="",설정!$C$24,$J20))) | Q20: =IF($O20="","",$O20-$I20-$P20) | R20: =IF(N($O20)=0,"",$Q20/$O20) | S20: =IF(N($M20)=0,"",$O20/$M20-1) | T20: =IF(N($L20)=0,"",$O20/$L20-1) | U20: =IF($O20="","",$O20*$H20) | V20: =IF($Q20="","",$Q20*$H20) | X20: =IF($O20="","",IFERROR(IF(설정!$C$27<=1,ROUND(IF(설정!$C$26="원가 가산",$O20*(1+IF($W20="",설정!$C$28,$W20)),$O20/(1-IF($W20="",설정!$C$28,$W20))),0),CEILING(IF(설정!$C$26="원가 가산",$O20*(1+IF($W20="",설정!$C$28,$W20)),$O20/(1-IF($W20="",설정!$C$28,$W20))),설정!$C$27)),0))
I21: =IF($D21="","",IF(OR($E21="USD",$E21="CNY"),IF(N($F21)=0,"",$F21*IF($E21="USD",설정!$C$11,설정!$C$12)*(1+IF($D21="수입",설정!$C$17,설정!$C$23))),IF(N($G21)=0,"",$G21*(1+IF($D21="수입",설정!$C$29,설정!$C$23))))) | L21: =IF($I21="","",IFERROR(IF(설정!$C$26="원가 가산",$I21*(1+IF($J21="",설정!$C$24,$J21)),$I21/(1-IF($J21="",설정!$C$24,$J21))),0)) | M21: =IF($I21="","",IFERROR(IF(설정!$C$27<=1,ROUND(IF(설정!$C$26="원가 가산",$L21*(1+IF($K21="",설정!$C$25,$K21)),$I21/(1-IF($J21="",설정!$C$24,$J21)-IF($K21="",설정!$C$25,$K21))),0),CEILING(IF(설정!$C$26="원가 가산",$L21*(1+IF($K21="",설정!$C$25,$K21)),$I21/(1-IF($J21="",설정!$C$24,$J21)-IF($K21="",설정!$C$25,$K21))),설정!$C$27)),0)) | O21: =IF($M21="","",IF($N21="",$M21,$N21)) | P21: =IF($O21="","",IF(설정!$C$26="원가 가산",$I21*IF($J21="",설정!$C$24,$J21),$O21*IF($J21="",설정!$C$24,$J21))) | Q21: =IF($O21="","",$O21-$I21-$P21) | R21: =IF(N($O21)=0,"",$Q21/$O21) | S21: =IF(N($M21)=0,"",$O21/$M21-1) | T21: =IF(N($L21)=0,"",$O21/$L21-1) | U21: =IF($O21="","",$O21*$H21) | V21: =IF($Q21="","",$Q21*$H21) | X21: =IF($O21="","",IFERROR(IF(설정!$C$27<=1,ROUND(IF(설정!$C$26="원가 가산",$O21*(1+IF($W21="",설정!$C$28,$W21)),$O21/(1-IF($W21="",설정!$C$28,$W21))),0),CEILING(IF(설정!$C$26="원가 가산",$O21*(1+IF($W21="",설정!$C$28,$W21)),$O21/(1-IF($W21="",설정!$C$28,$W21))),설정!$C$27)),0))
I22: =IF($D22="","",IF(OR($E22="USD",$E22="CNY"),IF(N($F22)=0,"",$F22*IF($E22="USD",설정!$C$11,설정!$C$12)*(1+IF($D22="수입",설정!$C$17,설정!$C$23))),IF(N($G22)=0,"",$G22*(1+IF($D22="수입",설정!$C$29,설정!$C$23))))) | L22: =IF($I22="","",IFERROR(IF(설정!$C$26="원가 가산",$I22*(1+IF($J22="",설정!$C$24,$J22)),$I22/(1-IF($J22="",설정!$C$24,$J22))),0)) | M22: =IF($I22="","",IFERROR(IF(설정!$C$27<=1,ROUND(IF(설정!$C$26="원가 가산",$L22*(1+IF($K22="",설정!$C$25,$K22)),$I22/(1-IF($J22="",설정!$C$24,$J22)-IF($K22="",설정!$C$25,$K22))),0),CEILING(IF(설정!$C$26="원가 가산",$L22*(1+IF($K22="",설정!$C$25,$K22)),$I22/(1-IF($J22="",설정!$C$24,$J22)-IF($K22="",설정!$C$25,$K22))),설정!$C$27)),0)) | O22: =IF($M22="","",IF($N22="",$M22,$N22)) | P22: =IF($O22="","",IF(설정!$C$26="원가 가산",$I22*IF($J22="",설정!$C$24,$J22),$O22*IF($J22="",설정!$C$24,$J22))) | Q22: =IF($O22="","",$O22-$I22-$P22) | R22: =IF(N($O22)=0,"",$Q22/$O22) | S22: =IF(N($M22)=0,"",$O22/$M22-1) | T22: =IF(N($L22)=0,"",$O22/$L22-1) | U22: =IF($O22="","",$O22*$H22) | V22: =IF($Q22="","",$Q22*$H22) | X22: =IF($O22="","",IFERROR(IF(설정!$C$27<=1,ROUND(IF(설정!$C$26="원가 가산",$O22*(1+IF($W22="",설정!$C$28,$W22)),$O22/(1-IF($W22="",설정!$C$28,$W22))),0),CEILING(IF(설정!$C$26="원가 가산",$O22*(1+IF($W22="",설정!$C$28,$W22)),$O22/(1-IF($W22="",설정!$C$28,$W22))),설정!$C$27)),0))
I23: =IF($D23="","",IF(OR($E23="USD",$E23="CNY"),IF(N($F23)=0,"",$F23*IF($E23="USD",설정!$C$11,설정!$C$12)*(1+IF($D23="수입",설정!$C$17,설정!$C$23))),IF(N($G23)=0,"",$G23*(1+IF($D23="수입",설정!$C$29,설정!$C$23))))) | L23: =IF($I23="","",IFERROR(IF(설정!$C$26="원가 가산",$I23*(1+IF($J23="",설정!$C$24,$J23)),$I23/(1-IF($J23="",설정!$C$24,$J23))),0)) | M23: =IF($I23="","",IFERROR(IF(설정!$C$27<=1,ROUND(IF(설정!$C$26="원가 가산",$L23*(1+IF($K23="",설정!$C$25,$K23)),$I23/(1-IF($J23="",설정!$C$24,$J23)-IF($K23="",설정!$C$25,$K23))),0),CEILING(IF(설정!$C$26="원가 가산",$L23*(1+IF($K23="",설정!$C$25,$K23)),$I23/(1-IF($J23="",설정!$C$24,$J23)-IF($K23="",설정!$C$25,$K23))),설정!$C$27)),0)) | O23: =IF($M23="","",IF($N23="",$M23,$N23)) | P23: =IF($O23="","",IF(설정!$C$26="원가 가산",$I23*IF($J23="",설정!$C$24,$J23),$O23*IF($J23="",설정!$C$24,$J23))) | Q23: =IF($O23="","",$O23-$I23-$P23) | R23: =IF(N($O23)=0,"",$Q23/$O23) | S23: =IF(N($M23)=0,"",$O23/$M23-1) | T23: =IF(N($L23)=0,"",$O23/$L23-1) | U23: =IF($O23="","",$O23*$H23) | V23: =IF($Q23="","",$Q23*$H23) | X23: =IF($O23="","",IFERROR(IF(설정!$C$27<=1,ROUND(IF(설정!$C$26="원가 가산",$O23*(1+IF($W23="",설정!$C$28,$W23)),$O23/(1-IF($W23="",설정!$C$28,$W23))),0),CEILING(IF(설정!$C$26="원가 가산",$O23*(1+IF($W23="",설정!$C$28,$W23)),$O23/(1-IF($W23="",설정!$C$28,$W23))),설정!$C$27)),0))
I24: =IF($D24="","",IF(OR($E24="USD",$E24="CNY"),IF(N($F24)=0,"",$F24*IF($E24="USD",설정!$C$11,설정!$C$12)*(1+IF($D24="수입",설정!$C$17,설정!$C$23))),IF(N($G24)=0,"",$G24*(1+IF($D24="수입",설정!$C$29,설정!$C$23))))) | L24: =IF($I24="","",IFERROR(IF(설정!$C$26="원가 가산",$I24*(1+IF($J24="",설정!$C$24,$J24)),$I24/(1-IF($J24="",설정!$C$24,$J24))),0)) | M24: =IF($I24="","",IFERROR(IF(설정!$C$27<=1,ROUND(IF(설정!$C$26="원가 가산",$L24*(1+IF($K24="",설정!$C$25,$K24)),$I24/(1-IF($J24="",설정!$C$24,$J24)-IF($K24="",설정!$C$25,$K24))),0),CEILING(IF(설정!$C$26="원가 가산",$L24*(1+IF($K24="",설정!$C$25,$K24)),$I24/(1-IF($J24="",설정!$C$24,$J24)-IF($K24="",설정!$C$25,$K24))),설정!$C$27)),0)) | O24: =IF($M24="","",IF($N24="",$M24,$N24)) | P24: =IF($O24="","",IF(설정!$C$26="원가 가산",$I24*IF($J24="",설정!$C$24,$J24),$O24*IF($J24="",설정!$C$24,$J24))) | Q24: =IF($O24="","",$O24-$I24-$P24) | R24: =IF(N($O24)=0,"",$Q24/$O24) | S24: =IF(N($M24)=0,"",$O24/$M24-1) | T24: =IF(N($L24)=0,"",$O24/$L24-1) | U24: =IF($O24="","",$O24*$H24) | V24: =IF($Q24="","",$Q24*$H24) | X24: =IF($O24="","",IFERROR(IF(설정!$C$27<=1,ROUND(IF(설정!$C$26="원가 가산",$O24*(1+IF($W24="",설정!$C$28,$W24)),$O24/(1-IF($W24="",설정!$C$28,$W24))),0),CEILING(IF(설정!$C$26="원가 가산",$O24*(1+IF($W24="",설정!$C$28,$W24)),$O24/(1-IF($W24="",설정!$C$28,$W24))),설정!$C$27)),0))
I25: =IF($D25="","",IF(OR($E25="USD",$E25="CNY"),IF(N($F25)=0,"",$F25*IF($E25="USD",설정!$C$11,설정!$C$12)*(1+IF($D25="수입",설정!$C$17,설정!$C$23))),IF(N($G25)=0,"",$G25*(1+IF($D25="수입",설정!$C$29,설정!$C$23))))) | L25: =IF($I25="","",IFERROR(IF(설정!$C$26="원가 가산",$I25*(1+IF($J25="",설정!$C$24,$J25)),$I25/(1-IF($J25="",설정!$C$24,$J25))),0)) | M25: =IF($I25="","",IFERROR(IF(설정!$C$27<=1,ROUND(IF(설정!$C$26="원가 가산",$L25*(1+IF($K25="",설정!$C$25,$K25)),$I25/(1-IF($J25="",설정!$C$24,$J25)-IF($K25="",설정!$C$25,$K25))),0),CEILING(IF(설정!$C$26="원가 가산",$L25*(1+IF($K25="",설정!$C$25,$K25)),$I25/(1-IF($J25="",설정!$C$24,$J25)-IF($K25="",설정!$C$25,$K25))),설정!$C$27)),0)) | O25: =IF($M25="","",IF($N25="",$M25,$N25)) | P25: =IF($O25="","",IF(설정!$C$26="원가 가산",$I25*IF($J25="",설정!$C$24,$J25),$O25*IF($J25="",설정!$C$24,$J25))) | Q25: =IF($O25="","",$O25-$I25-$P25) | R25: =IF(N($O25)=0,"",$Q25/$O25) | S25: =IF(N($M25)=0,"",$O25/$M25-1) | T25: =IF(N($L25)=0,"",$O25/$L25-1) | U25: =IF($O25="","",$O25*$H25) | V25: =IF($Q25="","",$Q25*$H25) | X25: =IF($O25="","",IFERROR(IF(설정!$C$27<=1,ROUND(IF(설정!$C$26="원가 가산",$O25*(1+IF($W25="",설정!$C$28,$W25)),$O25/(1-IF($W25="",설정!$C$28,$W25))),0),CEILING(IF(설정!$C$26="원가 가산",$O25*(1+IF($W25="",설정!$C$28,$W25)),$O25/(1-IF($W25="",설정!$C$28,$W25))),설정!$C$27)),0))
B26: 합계 | H26: =SUM(H6:H25) | R26: =IFERROR(SUM(V6:V25)/SUM(U6:U25),0) | U26: =SUM(U6:U25) | V26: =SUM(V6:V25)
B28: ① 금액은 통화가 정합니다 — USD·CNY면 F열(외화 단가), KRW면 G열(원화 매입단가)에 넣으세요.
B29: ② 부대비용률은 세 갈래입니다 — 수입+외화는 설정 C17, 수입+KRW(에이전트)는 설정 C29, 국내는 설정 C23.
B30: ③ J·K열을 비워 두면 설정 시트의 기본 판관비율·영업이익률이 적용됩니다.
B31: ④ M열 기준 유통가를 영업에 전달하고, 영업이 정한 값을 N열(노란 칸)에 적습니다. 비워 두면 기준가가 그대로 적용됩니다.
B32: ⑤ 최종 유통가가 BEP 가격보다 낮으면 N열이 빨갛게 표시됩니다 — 팔수록 손해라는 뜻입니다.
B33: ⑥ 소비자 판매가(X열)는 적용가에 소비자 마진율을 얹은 값입니다. W열을 비우면 설정 C28의 기본값이 쓰입니다.
B34: 표시 금액은 모두 부가세 별도입니다.

Sheet 태성재판매가산출
B2: 태성 재판매가 산출 — 플로우텍 공급가를 원가로
B3: ="태성 입고가(= 플로우텍 판매단가) → 추가비용 "&TEXT(설정!$C$32,"0.0%")&" → 판관비 "&TEXT(설정!$C$33,"0.0%")&" → BEP 가격 → 영업이익 "&TEXT(설정!$C$34,"0.0%")&" → 기준 판매가 → (영업) 최종 판매가 · "&설정!$C$26&" 방식"
B5: 품목 | C5: 품목코드 | D5: 조회 입고가 | E5: 입고가 직접 입력 | F5: 적용 입고가 | G5: 수량 | H5: 매입원가 /개 | I5: 판관비율 | J5: 영업이익률 | K5: BEP 가격 | L5: 기준 판매가 | M5: 최종 판매가 (영업 입력) | N5: 적용가 | O5: 판관비 /개 | P5: 영업이익 /개 | Q5: 영업이익률 (실제) | R5: 기준가 대비 | S5: BEP 대비 | T5: 소비자 마진율 | U5: 소비자 판매가 | V5: 매출 합계 | W5: 영업이익 합계
D6: =IF($C6="","",IFERROR(INDEX(자재판매가산출!$K$6:$K$24,MATCH($C6,자재판매가산출!$C$6:$C$24,0)),"")) | F6: =IF($E6<>"",$E6,IF(N($D6)=0,"",$D6)) | H6: =IF($F6="","",$F6*(1+설정!$C$32)) | K6: =IF($H6="","",IFERROR(IF(설정!$C$26="원가 가산",$H6*(1+IF($I6="",설정!$C$33,$I6)),$H6/(1-IF($I6="",설정!$C$33,$I6))),0)) | L6: =IF($H6="","",IFERROR(IF(설정!$C$27<=1,ROUND(IF(설정!$C$26="원가 가산",$K6*(1+IF($J6="",설정!$C$34,$J6)),$H6/(1-IF($I6="",설정!$C$33,$I6)-IF($J6="",설정!$C$34,$J6))),0),CEILING(IF(설정!$C$26="원가 가산",$K6*(1+IF($J6="",설정!$C$34,$J6)),$H6/(1-IF($I6="",설정!$C$33,$I6)-IF($J6="",설정!$C$34,$J6))),설정!$C$27)),0)) | N6: =IF($L6="","",IF($M6="",$L6,$M6)) | O6: =IF($N6="","",IF(설정!$C$26="원가 가산",$H6*IF($I6="",설정!$C$33,$I6),$N6*IF($I6="",설정!$C$33,$I6))) | P6: =IF($N6="","",$N6-$H6-$O6) | Q6: =IF(N($N6)=0,"",$P6/$N6) | R6: =IF(N($L6)=0,"",$N6/$L6-1) | S6: =IF(N($K6)=0,"",$N6/$K6-1) | U6: =IF($N6="","",IFERROR(IF(설정!$C$27<=1,ROUND(IF(설정!$C$26="원가 가산",$N6*(1+IF($T6="",설정!$C$28,$T6)),$N6/(1-IF($T6="",설정!$C$28,$T6))),0),CEILING(IF(설정!$C$26="원가 가산",$N6*(1+IF($T6="",설정!$C$28,$T6)),$N6/(1-IF($T6="",설정!$C$28,$T6))),설정!$C$27)),0)) | V6: =IF($N6="","",$N6*$G6) | W6: =IF($P6="","",$P6*$G6)
D7: =IF($C7="","",IFERROR(INDEX(자재판매가산출!$K$6:$K$24,MATCH($C7,자재판매가산출!$C$6:$C$24,0)),"")) | F7: =IF($E7<>"",$E7,IF(N($D7)=0,"",$D7)) | H7: =IF($F7="","",$F7*(1+설정!$C$32)) | K7: =IF($H7="","",IFERROR(IF(설정!$C$26="원가 가산",$H7*(1+IF($I7="",설정!$C$33,$I7)),$H7/(1-IF($I7="",설정!$C$33,$I7))),0)) | L7: =IF($H7="","",IFERROR(IF(설정!$C$27<=1,ROUND(IF(설정!$C$26="원가 가산",$K7*(1+IF($J7="",설정!$C$34,$J7)),$H7/(1-IF($I7="",설정!$C$33,$I7)-IF($J7="",설정!$C$34,$J7))),0),CEILING(IF(설정!$C$26="원가 가산",$K7*(1+IF($J7="",설정!$C$34,$J7)),$H7/(1-IF($I7="",설정!$C$33,$I7)-IF($J7="",설정!$C$34,$J7))),설정!$C$27)),0)) | N7: =IF($L7="","",IF($M7="",$L7,$M7)) | O7: =IF($N7="","",IF(설정!$C$26="원가 가산",$H7*IF($I7="",설정!$C$33,$I7),$N7*IF($I7="",설정!$C$33,$I7))) | P7: =IF($N7="","",$N7-$H7-$O7) | Q7: =IF(N($N7)=0,"",$P7/$N7) | R7: =IF(N($L7)=0,"",$N7/$L7-1) | S7: =IF(N($K7)=0,"",$N7/$K7-1) | U7: =IF($N7="","",IFERROR(IF(설정!$C$27<=1,ROUND(IF(설정!$C$26="원가 가산",$N7*(1+IF($T7="",설정!$C$28,$T7)),$N7/(1-IF($T7="",설정!$C$28,$T7))),0),CEILING(IF(설정!$C$26="원가 가산",$N7*(1+IF($T7="",설정!$C$28,$T7)),$N7/(1-IF($T7="",설정!$C$28,$T7))),설정!$C$27)),0)) | V7: =IF($N7="","",$N7*$G7) | W7: =IF($P7="","",$P7*$G7)
D8: =IF($C8="","",IFERROR(INDEX(자재판매가산출!$K$6:$K$24,MATCH($C8,자재판매가산출!$C$6:$C$24,0)),"")) | F8: =IF($E8<>"",$E8,IF(N($D8)=0,"",$D8)) | H8: =IF($F8="","",$F8*(1+설정!$C$32)) | K8: =IF($H8="","",IFERROR(IF(설정!$C$26="원가 가산",$H8*(1+IF($I8="",설정!$C$33,$I8)),$H8/(1-IF($I8="",설정!$C$33,$I8))),0)) | L8: =IF($H8="","",IFERROR(IF(설정!$C$27<=1,ROUND(IF(설정!$C$26="원가 가산",$K8*(1+IF($J8="",설정!$C$34,$J8)),$H8/(1-IF($I8="",설정!$C$33,$I8)-IF($J8="",설정!$C$34,$J8))),0),CEILING(IF(설정!$C$26="원가 가산",$K8*(1+IF($J8="",설정!$C$34,$J8)),$H8/(1-IF($I8="",설정!$C$33,$I8)-IF($J8="",설정!$C$34,$J8))),설정!$C$27)),0)) | N8: =IF($L8="","",IF($M8="",$L8,$M8)) | O8: =IF($N8="","",IF(설정!$C$26="원가 가산",$H8*IF($I8="",설정!$C$33,$I8),$N8*IF($I8="",설정!$C$33,$I8))) | P8: =IF($N8="","",$N8-$H8-$O8) | Q8: =IF(N($N8)=0,"",$P8/$N8) | R8: =IF(N($L8)=0,"",$N8/$L8-1) | S8: =IF(N($K8)=0,"",$N8/$K8-1) | U8: =IF($N8="","",IFERROR(IF(설정!$C$27<=1,ROUND(IF(설정!$C$26="원가 가산",$N8*(1+IF($T8="",설정!$C$28,$T8)),$N8/(1-IF($T8="",설정!$C$28,$T8))),0),CEILING(IF(설정!$C$26="원가 가산",$N8*(1+IF($T8="",설정!$C$28,$T8)),$N8/(1-IF($T8="",설정!$C$28,$T8))),설정!$C$27)),0)) | V8: =IF($N8="","",$N8*$G8) | W8: =IF($P8="","",$P8*$G8)
D9: =IF($C9="","",IFERROR(INDEX(자재판매가산출!$K$6:$K$24,MATCH($C9,자재판매가산출!$C$6:$C$24,0)),"")) | F9: =IF($E9<>"",$E9,IF(N($D9)=0,"",$D9)) | H9: =IF($F9="","",$F9*(1+설정!$C$32)) | K9: =IF($H9="","",IFERROR(IF(설정!$C$26="원가 가산",$H9*(1+IF($I9="",설정!$C$33,$I9)),$H9/(1-IF($I9="",설정!$C$33,$I9))),0)) | L9: =IF($H9="","",IFERROR(IF(설정!$C$27<=1,ROUND(IF(설정!$C$26="원가 가산",$K9*(1+IF($J9="",설정!$C$34,$J9)),$H9/(1-IF($I9="",설정!$C$33,$I9)-IF($J9="",설정!$C$34,$J9))),0),CEILING(IF(설정!$C$26="원가 가산",$K9*(1+IF($J9="",설정!$C$34,$J9)),$H9/(1-IF($I9="",설정!$C$33,$I9)-IF($J9="",설정!$C$34,$J9))),설정!$C$27)),0)) | N9: =IF($L9="","",IF($M9="",$L9,$M9)) | O9: =IF($N9="","",IF(설정!$C$26="원가 가산",$H9*IF($I9="",설정!$C$33,$I9),$N9*IF($I9="",설정!$C$33,$I9))) | P9: =IF($N9="","",$N9-$H9-$O9) | Q9: =IF(N($N9)=0,"",$P9/$N9) | R9: =IF(N($L9)=0,"",$N9/$L9-1) | S9: =IF(N($K9)=0,"",$N9/$K9-1) | U9: =IF($N9="","",IFERROR(IF(설정!$C$27<=1,ROUND(IF(설정!$C$26="원가 가산",$N9*(1+IF($T9="",설정!$C$28,$T9)),$N9/(1-IF($T9="",설정!$C$28,$T9))),0),CEILING(IF(설정!$C$26="원가 가산",$N9*(1+IF($T9="",설정!$C$28,$T9)),$N9/(1-IF($T9="",설정!$C$28,$T9))),설정!$C$27)),0)) | V9: =IF($N9="","",$N9*$G9) | W9: =IF($P9="","",$P9*$G9)
D10: =IF($C10="","",IFERROR(INDEX(자재판매가산출!$K$6:$K$24,MATCH($C10,자재판매가산출!$C$6:$C$24,0)),"")) | F10: =IF($E10<>"",$E10,IF(N($D10)=0,"",$D10)) | H10: =IF($F10="","",$F10*(1+설정!$C$32)) | K10: =IF($H10="","",IFERROR(IF(설정!$C$26="원가 가산",$H10*(1+IF($I10="",설정!$C$33,$I10)),$H10/(1-IF($I10="",설정!$C$33,$I10))),0)) | L10: =IF($H10="","",IFERROR(IF(설정!$C$27<=1,ROUND(IF(설정!$C$26="원가 가산",$K10*(1+IF($J10="",설정!$C$34,$J10)),$H10/(1-IF($I10="",설정!$C$33,$I10)-IF($J10="",설정!$C$34,$J10))),0),CEILING(IF(설정!$C$26="원가 가산",$K10*(1+IF($J10="",설정!$C$34,$J10)),$H10/(1-IF($I10="",설정!$C$33,$I10)-IF($J10="",설정!$C$34,$J10))),설정!$C$27)),0)) | N10: =IF($L10="","",IF($M10="",$L10,$M10)) | O10: =IF($N10="","",IF(설정!$C$26="원가 가산",$H10*IF($I10="",설정!$C$33,$I10),$N10*IF($I10="",설정!$C$33,$I10))) | P10: =IF($N10="","",$N10-$H10-$O10) | Q10: =IF(N($N10)=0,"",$P10/$N10) | R10: =IF(N($L10)=0,"",$N10/$L10-1) | S10: =IF(N($K10)=0,"",$N10/$K10-1) | U10: =IF($N10="","",IFERROR(IF(설정!$C$27<=1,ROUND(IF(설정!$C$26="원가 가산",$N10*(1+IF($T10="",설정!$C$28,$T10)),$N10/(1-IF($T10="",설정!$C$28,$T10))),0),CEILING(IF(설정!$C$26="원가 가산",$N10*(1+IF($T10="",설정!$C$28,$T10)),$N10/(1-IF($T10="",설정!$C$28,$T10))),설정!$C$27)),0)) | V10: =IF($N10="","",$N10*$G10) | W10: =IF($P10="","",$P10*$G10)
D11: =IF($C11="","",IFERROR(INDEX(자재판매가산출!$K$6:$K$24,MATCH($C11,자재판매가산출!$C$6:$C$24,0)),"")) | F11: =IF($E11<>"",$E11,IF(N($D11)=0,"",$D11)) | H11: =IF($F11="","",$F11*(1+설정!$C$32)) | K11: =IF($H11="","",IFERROR(IF(설정!$C$26="원가 가산",$H11*(1+IF($I11="",설정!$C$33,$I11)),$H11/(1-IF($I11="",설정!$C$33,$I11))),0)) | L11: =IF($H11="","",IFERROR(IF(설정!$C$27<=1,ROUND(IF(설정!$C$26="원가 가산",$K11*(1+IF($J11="",설정!$C$34,$J11)),$H11/(1-IF($I11="",설정!$C$33,$I11)-IF($J11="",설정!$C$34,$J11))),0),CEILING(IF(설정!$C$26="원가 가산",$K11*(1+IF($J11="",설정!$C$34,$J11)),$H11/(1-IF($I11="",설정!$C$33,$I11)-IF($J11="",설정!$C$34,$J11))),설정!$C$27)),0)) | N11: =IF($L11="","",IF($M11="",$L11,$M11)) | O11: =IF($N11="","",IF(설정!$C$26="원가 가산",$H11*IF($I11="",설정!$C$33,$I11),$N11*IF($I11="",설정!$C$33,$I11))) | P11: =IF($N11="","",$N11-$H11-$O11) | Q11: =IF(N($N11)=0,"",$P11/$N11) | R11: =IF(N($L11)=0,"",$N11/$L11-1) | S11: =IF(N($K11)=0,"",$N11/$K11-1) | U11: =IF($N11="","",IFERROR(IF(설정!$C$27<=1,ROUND(IF(설정!$C$26="원가 가산",$N11*(1+IF($T11="",설정!$C$28,$T11)),$N11/(1-IF($T11="",설정!$C$28,$T11))),0),CEILING(IF(설정!$C$26="원가 가산",$N11*(1+IF($T11="",설정!$C$28,$T11)),$N11/(1-IF($T11="",설정!$C$28,$T11))),설정!$C$27)),0)) | V11: =IF($N11="","",$N11*$G11) | W11: =IF($P11="","",$P11*$G11)
D12: =IF($C12="","",IFERROR(INDEX(자재판매가산출!$K$6:$K$24,MATCH($C12,자재판매가산출!$C$6:$C$24,0)),"")) | F12: =IF($E12<>"",$E12,IF(N($D12)=0,"",$D12)) | H12: =IF($F12="","",$F12*(1+설정!$C$32)) | K12: =IF($H12="","",IFERROR(IF(설정!$C$26="원가 가산",$H12*(1+IF($I12="",설정!$C$33,$I12)),$H12/(1-IF($I12="",설정!$C$33,$I12))),0)) | L12: =IF($H12="","",IFERROR(IF(설정!$C$27<=1,ROUND(IF(설정!$C$26="원가 가산",$K12*(1+IF($J12="",설정!$C$34,$J12)),$H12/(1-IF($I12="",설정!$C$33,$I12)-IF($J12="",설정!$C$34,$J12))),0),CEILING(IF(설정!$C$26="원가 가산",$K12*(1+IF($J12="",설정!$C$34,$J12)),$H12/(1-IF($I12="",설정!$C$33,$I12)-IF($J12="",설정!$C$34,$J12))),설정!$C$27)),0)) | N12: =IF($L12="","",IF($M12="",$L12,$M12)) | O12: =IF($N12="","",IF(설정!$C$26="원가 가산",$H12*IF($I12="",설정!$C$33,$I12),$N12*IF($I12="",설정!$C$33,$I12))) | P12: =IF($N12="","",$N12-$H12-$O12) | Q12: =IF(N($N12)=0,"",$P12/$N12) | R12: =IF(N($L12)=0,"",$N12/$L12-1) | S12: =IF(N($K12)=0,"",$N12/$K12-1) | U12: =IF($N12="","",IFERROR(IF(설정!$C$27<=1,ROUND(IF(설정!$C$26="원가 가산",$N12*(1+IF($T12="",설정!$C$28,$T12)),$N12/(1-IF($T12="",설정!$C$28,$T12))),0),CEILING(IF(설정!$C$26="원가 가산",$N12*(1+IF($T12="",설정!$C$28,$T12)),$N12/(1-IF($T12="",설정!$C$28,$T12))),설정!$C$27)),0)) | V12: =IF($N12="","",$N12*$G12) | W12: =IF($P12="","",$P12*$G12)
D13: =IF($C13="","",IFERROR(INDEX(자재판매가산출!$K$6:$K$24,MATCH($C13,자재판매가산출!$C$6:$C$24,0)),"")) | F13: =IF($E13<>"",$E13,IF(N($D13)=0,"",$D13)) | H13: =IF($F13="","",$F13*(1+설정!$C$32)) | K13: =IF($H13="","",IFERROR(IF(설정!$C$26="원가 가산",$H13*(1+IF($I13="",설정!$C$33,$I13)),$H13/(1-IF($I13="",설정!$C$33,$I13))),0)) | L13: =IF($H13="","",IFERROR(IF(설정!$C$27<=1,ROUND(IF(설정!$C$26="원가 가산",$K13*(1+IF($J13="",설정!$C$34,$J13)),$H13/(1-IF($I13="",설정!$C$33,$I13)-IF($J13="",설정!$C$34,$J13))),0),CEILING(IF(설정!$C$26="원가 가산",$K13*(1+IF($J13="",설정!$C$34,$J13)),$H13/(1-IF($I13="",설정!$C$33,$I13)-IF($J13="",설정!$C$34,$J13))),설정!$C$27)),0)) | N13: =IF($L13="","",IF($M13="",$L13,$M13)) | O13: =IF($N13="","",IF(설정!$C$26="원가 가산",$H13*IF($I13="",설정!$C$33,$I13),$N13*IF($I13="",설정!$C$33,$I13))) | P13: =IF($N13="","",$N13-$H13-$O13) | Q13: =IF(N($N13)=0,"",$P13/$N13) | R13: =IF(N($L13)=0,"",$N13/$L13-1) | S13: =IF(N($K13)=0,"",$N13/$K13-1) | U13: =IF($N13="","",IFERROR(IF(설정!$C$27<=1,ROUND(IF(설정!$C$26="원가 가산",$N13*(1+IF($T13="",설정!$C$28,$T13)),$N13/(1-IF($T13="",설정!$C$28,$T13))),0),CEILING(IF(설정!$C$26="원가 가산",$N13*(1+IF($T13="",설정!$C$28,$T13)),$N13/(1-IF($T13="",설정!$C$28,$T13))),설정!$C$27)),0)) | V13: =IF($N13="","",$N13*$G13) | W13: =IF($P13="","",$P13*$G13)
D14: =IF($C14="","",IFERROR(INDEX(자재판매가산출!$K$6:$K$24,MATCH($C14,자재판매가산출!$C$6:$C$24,0)),"")) | F14: =IF($E14<>"",$E14,IF(N($D14)=0,"",$D14)) | H14: =IF($F14="","",$F14*(1+설정!$C$32)) | K14: =IF($H14="","",IFERROR(IF(설정!$C$26="원가 가산",$H14*(1+IF($I14="",설정!$C$33,$I14)),$H14/(1-IF($I14="",설정!$C$33,$I14))),0)) | L14: =IF($H14="","",IFERROR(IF(설정!$C$27<=1,ROUND(IF(설정!$C$26="원가 가산",$K14*(1+IF($J14="",설정!$C$34,$J14)),$H14/(1-IF($I14="",설정!$C$33,$I14)-IF($J14="",설정!$C$34,$J14))),0),CEILING(IF(설정!$C$26="원가 가산",$K14*(1+IF($J14="",설정!$C$34,$J14)),$H14/(1-IF($I14="",설정!$C$33,$I14)-IF($J14="",설정!$C$34,$J14))),설정!$C$27)),0)) | N14: =IF($L14="","",IF($M14="",$L14,$M14)) | O14: =IF($N14="","",IF(설정!$C$26="원가 가산",$H14*IF($I14="",설정!$C$33,$I14),$N14*IF($I14="",설정!$C$33,$I14))) | P14: =IF($N14="","",$N14-$H14-$O14) | Q14: =IF(N($N14)=0,"",$P14/$N14) | R14: =IF(N($L14)=0,"",$N14/$L14-1) | S14: =IF(N($K14)=0,"",$N14/$K14-1) | U14: =IF($N14="","",IFERROR(IF(설정!$C$27<=1,ROUND(IF(설정!$C$26="원가 가산",$N14*(1+IF($T14="",설정!$C$28,$T14)),$N14/(1-IF($T14="",설정!$C$28,$T14))),0),CEILING(IF(설정!$C$26="원가 가산",$N14*(1+IF($T14="",설정!$C$28,$T14)),$N14/(1-IF($T14="",설정!$C$28,$T14))),설정!$C$27)),0)) | V14: =IF($N14="","",$N14*$G14) | W14: =IF($P14="","",$P14*$G14)
D15: =IF($C15="","",IFERROR(INDEX(자재판매가산출!$K$6:$K$24,MATCH($C15,자재판매가산출!$C$6:$C$24,0)),"")) | F15: =IF($E15<>"",$E15,IF(N($D15)=0,"",$D15)) | H15: =IF($F15="","",$F15*(1+설정!$C$32)) | K15: =IF($H15="","",IFERROR(IF(설정!$C$26="원가 가산",$H15*(1+IF($I15="",설정!$C$33,$I15)),$H15/(1-IF($I15="",설정!$C$33,$I15))),0)) | L15: =IF($H15="","",IFERROR(IF(설정!$C$27<=1,ROUND(IF(설정!$C$26="원가 가산",$K15*(1+IF($J15="",설정!$C$34,$J15)),$H15/(1-IF($I15="",설정!$C$33,$I15)-IF($J15="",설정!$C$34,$J15))),0),CEILING(IF(설정!$C$26="원가 가산",$K15*(1+IF($J15="",설정!$C$34,$J15)),$H15/(1-IF($I15="",설정!$C$33,$I15)-IF($J15="",설정!$C$34,$J15))),설정!$C$27)),0)) | N15: =IF($L15="","",IF($M15="",$L15,$M15)) | O15: =IF($N15="","",IF(설정!$C$26="원가 가산",$H15*IF($I15="",설정!$C$33,$I15),$N15*IF($I15="",설정!$C$33,$I15))) | P15: =IF($N15="","",$N15-$H15-$O15) | Q15: =IF(N($N15)=0,"",$P15/$N15) | R15: =IF(N($L15)=0,"",$N15/$L15-1) | S15: =IF(N($K15)=0,"",$N15/$K15-1) | U15: =IF($N15="","",IFERROR(IF(설정!$C$27<=1,ROUND(IF(설정!$C$26="원가 가산",$N15*(1+IF($T15="",설정!$C$28,$T15)),$N15/(1-IF($T15="",설정!$C$28,$T15))),0),CEILING(IF(설정!$C$26="원가 가산",$N15*(1+IF($T15="",설정!$C$28,$T15)),$N15/(1-IF($T15="",설정!$C$28,$T15))),설정!$C$27)),0)) | V15: =IF($N15="","",$N15*$G15) | W15: =IF($P15="","",$P15*$G15)
D16: =IF($C16="","",IFERROR(INDEX(자재판매가산출!$K$6:$K$24,MATCH($C16,자재판매가산출!$C$6:$C$24,0)),"")) | F16: =IF($E16<>"",$E16,IF(N($D16)=0,"",$D16)) | H16: =IF($F16="","",$F16*(1+설정!$C$32)) | K16: =IF($H16="","",IFERROR(IF(설정!$C$26="원가 가산",$H16*(1+IF($I16="",설정!$C$33,$I16)),$H16/(1-IF($I16="",설정!$C$33,$I16))),0)) | L16: =IF($H16="","",IFERROR(IF(설정!$C$27<=1,ROUND(IF(설정!$C$26="원가 가산",$K16*(1+IF($J16="",설정!$C$34,$J16)),$H16/(1-IF($I16="",설정!$C$33,$I16)-IF($J16="",설정!$C$34,$J16))),0),CEILING(IF(설정!$C$26="원가 가산",$K16*(1+IF($J16="",설정!$C$34,$J16)),$H16/(1-IF($I16="",설정!$C$33,$I16)-IF($J16="",설정!$C$34,$J16))),설정!$C$27)),0)) | N16: =IF($L16="","",IF($M16="",$L16,$M16)) | O16: =IF($N16="","",IF(설정!$C$26="원가 가산",$H16*IF($I16="",설정!$C$33,$I16),$N16*IF($I16="",설정!$C$33,$I16))) | P16: =IF($N16="","",$N16-$H16-$O16) | Q16: =IF(N($N16)=0,"",$P16/$N16) | R16: =IF(N($L16)=0,"",$N16/$L16-1) | S16: =IF(N($K16)=0,"",$N16/$K16-1) | U16: =IF($N16="","",IFERROR(IF(설정!$C$27<=1,ROUND(IF(설정!$C$26="원가 가산",$N16*(1+IF($T16="",설정!$C$28,$T16)),$N16/(1-IF($T16="",설정!$C$28,$T16))),0),CEILING(IF(설정!$C$26="원가 가산",$N16*(1+IF($T16="",설정!$C$28,$T16)),$N16/(1-IF($T16="",설정!$C$28,$T16))),설정!$C$27)),0)) | V16: =IF($N16="","",$N16*$G16) | W16: =IF($P16="","",$P16*$G16)
D17: =IF($C17="","",IFERROR(INDEX(자재판매가산출!$K$6:$K$24,MATCH($C17,자재판매가산출!$C$6:$C$24,0)),"")) | F17: =IF($E17<>"",$E17,IF(N($D17)=0,"",$D17)) | H17: =IF($F17="","",$F17*(1+설정!$C$32)) | K17: =IF($H17="","",IFERROR(IF(설정!$C$26="원가 가산",$H17*(1+IF($I17="",설정!$C$33,$I17)),$H17/(1-IF($I17="",설정!$C$33,$I17))),0)) | L17: =IF($H17="","",IFERROR(IF(설정!$C$27<=1,ROUND(IF(설정!$C$26="원가 가산",$K17*(1+IF($J17="",설정!$C$34,$J17)),$H17/(1-IF($I17="",설정!$C$33,$I17)-IF($J17="",설정!$C$34,$J17))),0),CEILING(IF(설정!$C$26="원가 가산",$K17*(1+IF($J17="",설정!$C$34,$J17)),$H17/(1-IF($I17="",설정!$C$33,$I17)-IF($J17="",설정!$C$34,$J17))),설정!$C$27)),0)) | N17: =IF($L17="","",IF($M17="",$L17,$M17)) | O17: =IF($N17="","",IF(설정!$C$26="원가 가산",$H17*IF($I17="",설정!$C$33,$I17),$N17*IF($I17="",설정!$C$33,$I17))) | P17: =IF($N17="","",$N17-$H17-$O17) | Q17: =IF(N($N17)=0,"",$P17/$N17) | R17: =IF(N($L17)=0,"",$N17/$L17-1) | S17: =IF(N($K17)=0,"",$N17/$K17-1) | U17: =IF($N17="","",IFERROR(IF(설정!$C$27<=1,ROUND(IF(설정!$C$26="원가 가산",$N17*(1+IF($T17="",설정!$C$28,$T17)),$N17/(1-IF($T17="",설정!$C$28,$T17))),0),CEILING(IF(설정!$C$26="원가 가산",$N17*(1+IF($T17="",설정!$C$28,$T17)),$N17/(1-IF($T17="",설정!$C$28,$T17))),설정!$C$27)),0)) | V17: =IF($N17="","",$N17*$G17) | W17: =IF($P17="","",$P17*$G17)
... D25: =IF($C25="","",IFERROR(INDEX(자재판매가산출!$K$6:$K$24,MATCH($C25,자재판매가산출!$C$6:$C$24,0)),"")) | F25: =IF($E25<>"",$E25,IF(N($D25)=0,"",$D25)) | H25: =IF($F25="","",$F25*(1+설정!$C$32)) | K25: =IF($H25="","",IFERROR(IF(설정!$C$26="원가 가산",$H25*(1+IF($I25="",설정!$C$33,$I25)),$H25/(1-IF($I25="",설정!$C$33,$I25))),0)) | L25: =IF($H25="","",IFERROR(IF(설정!$C$27<=1,ROUND(IF(설정!$C$26="원가 가산",$K25*(1+IF($J25="",설정!$C$34,$J25)),$H25/(1-IF($I25="",설정!$C$33,$I25)-IF($J25="",설정!$C$34,$J25))),0),CEILING(IF(설정!$C$26="원가 가산",$K25*(1+IF($J25="",설정!$C$34,$J25)),$H25/(1-IF($I25="",설정!$C$33,$I25)-IF($J25="",설정!$C$34,$J25))),설정!$C$27)),0)) | N25: =IF($L25="","",IF($M25="",$L25,$M25)) | O25: =IF($N25="","",IF(설정!$C$26="원가 가산",$H25*IF($I25="",설정!$C$33,$I25),$N25*IF($I25="",설정!$C$33,$I25))) | P25: =IF($N25="","",$N25-$H25-$O25) | Q25: =IF(N($N25)=0,"",$P25/$N25) | R25: =IF(N($L25)=0,"",$N25/$L25-1) | S25: =IF(N($K25)=0,"",$N25/$K25-1) | U25: =IF($N25="","",IFERROR(IF(설정!$C$27<=1,ROUND(IF(설정!$C$26="원가 가산",$N25*(1+IF($T25="",설정!$C$28,$T25)),$N25/(1-IF($T25="",설정!$C$28,$T25))),0),CEILING(IF(설정!$C$26="원가 가산",$N25*(1+IF($T25="",설정!$C$28,$T25)),$N25/(1-IF($T25="",설정!$C$28,$T25))),설정!$C$27)),0)) | V25: =IF($N25="","",$N25*$G25) | W25: =IF($P25="","",$P25*$G25)
B26: 합계 | G26: =SUM(G6:G25) | Q26: =IFERROR(SUM(W6:W25)/SUM(V6:V25),0) | V26: =SUM(V6:V25) | W26: =SUM(W6:W25)
B28: ① 품목코드(C열)를 넣으면 자재판매가산출 시트에서 그 품목의 판매단가를 찾아 D열에 가져옵니다 — 그것이 태성 입고가입니다.
B29: ② D열이 비면 그 코드가 자재판매가산출에 없다는 뜻입니다. 그럴 때는 E열에 입고가를 직접 넣으세요. E열에 값이 있으면 조회값보다 우선합니다.
B30: ③ 태성 입고가가 곧 원가입니다. 입고 후 운반비 등이 붙으면 설정 C32(태성 추가비용률)에 넣으세요.
B31: ④ 판관비율·영업이익률은 설정 C33·C34(태성 기준)를 씁니다. 플로우텍 상품 판매가의 값(C24·C25)과는 별개입니다.
B32: ⑤ L열 기준 판매가를 영업에 전달하고, 영업이 정한 값을 M열(노란 칸)에 적습니다. 비워 두면 기준가가 그대로 적용됩니다.
B33: ⑥ 최종 판매가가 BEP 가격보다 낮으면 M열이 빨갛게 표시됩니다 — 팔수록 손해라는 뜻입니다.
B34: 표시 금액은 모두 부가세 별도입니다.

Sheet Sheet1
C4: 번호 | D4: 품명 | E4: 몸통 | G4: 행거 | I4: 샤워헤드 | K4: 메탈호스
B5: #VALUE! | C5: 1 | D5: 원홀세면수전 | E5: #VALUE!
C6: 2 | D6: 욕조수전 | E6: #VALUE! | G6: #VALUE! | H6: #VALUE! | I6: #VALUE! | J6: #VALUE! | K6: #VALUE!
C7: 3 | D7: 원홀세면수전 | E7: #VALUE!
C8: 4 | D8: 욕조수전 | E8: #VALUE! | F8: #VALUE! | G8: #VALUE! | H8: #VALUE! | I8: #VALUE! | J8: #VALUE! | K8: #VALUE!

Sheet 유통가 보고
B2: 최종 유통가 보고
B3: ="적용 연월 "&설정!$C$8&" · USD "&TEXT(설정!$C$11,"#,##0.00")&" · CNY "&TEXT(설정!$C$12,"#,##0.00")&" · 판관비 "&TEXT(설정!$C$24,"0.0%")&" · 목표 영업이익 "&TEXT(설정!$C$25,"0.0%")&" · 소비자 마진 "&TEXT(설정!$C$28,"0.0%")&" · "&설정!$C$26&" 방식"
B4: ="작성일 "&TEXT(TODAY(),"YYYY-MM-DD")&" | 금액은 모두 부가세 별도"
B6: 상품 | C6: 품목코드 | D6: 매입단가 | E6: 수량 | F6: BEP 가격 | G6: 최종 유통가 | H6: 소비자 판매가 | I6: 영업이익률 (실제) | J6: 매출 합계 | K6: 영업이익 합계
B7: =IF(상품판매가산출!$B6="","",상품판매가산출!$B6) | C7: =IF(상품판매가산출!$B6="","",상품판매가산출!$C6) | D7: =IF(상품판매가산출!$B6="","",상품판매가산출!$I6) | E7: =IF(상품판매가산출!$B6="","",상품판매가산출!$H6) | F7: =IF(상품판매가산출!$B6="","",상품판매가산출!$L6) | G7: =IF(상품판매가산출!$B6="","",상품판매가산출!$O6) | H7: =IF(상품판매가산출!$B6="","",상품판매가산출!$X6) | I7: =IF(상품판매가산출!$B6="","",상품판매가산출!$R6) | J7: =IF(상품판매가산출!$B6="","",상품판매가산출!$U6) | K7: =IF(상품판매가산출!$B6="","",상품판매가산출!$V6)
B8: =IF(상품판매가산출!$B7="","",상품판매가산출!$B7) | C8: =IF(상품판매가산출!$B7="","",상품판매가산출!$C7) | D8: =IF(상품판매가산출!$B7="","",상품판매가산출!$I7) | E8: =IF(상품판매가산출!$B7="","",상품판매가산출!$H7) | F8: =IF(상품판매가산출!$B7="","",상품판매가산출!$L7) | G8: =IF(상품판매가산출!$B7="","",상품판매가산출!$O7) | H8: =IF(상품판매가산출!$B7="","",상품판매가산출!$X7) | I8: =IF(상품판매가산출!$B7="","",상품판매가산출!$R7) | J8: =IF(상품판매가산출!$B7="","",상품판매가산출!$U7) | K8: =IF(상품판매가산출!$B7="","",상품판매가산출!$V7)
B9: =IF(상품판매가산출!$B8="","",상품판매가산출!$B8) | C9: =IF(상품판매가산출!$B8="","",상품판매가산출!$C8) | D9: =IF(상품판매가산출!$B8="","",상품판매가산출!$I8) | E9: =IF(상품판매가산출!$B8="","",상품판매가산출!$H8) | F9: =IF(상품판매가산출!$B8="","",상품판매가산출!$L8) | G9: =IF(상품판매가산출!$B8="","",상품판매가산출!$O8) | H9: =IF(상품판매가산출!$B8="","",상품판매가산출!$X8) | I9: =IF(상품판매가산출!$B8="","",상품판매가산출!$R8) | J9: =IF(상품판매가산출!$B8="","",상품판매가산출!$U8) | K9: =IF(상품판매가산출!$B8="","",상품판매가산출!$V8)
B10: =IF(상품판매가산출!$B9="","",상품판매가산출!$B9) | C10: =IF(상품판매가산출!$B9="","",상품판매가산출!$C9) | D10: =IF(상품판매가산출!$B9="","",상품판매가산출!$I9) | E10: =IF(상품판매가산출!$B9="","",상품판매가산출!$H9) | F10: =IF(상품판매가산출!$B9="","",상품판매가산출!$L9) | G10: =IF(상품판매가산출!$B9="","",상품판매가산출!$O9) | H10: =IF(상품판매가산출!$B9="","",상품판매가산출!$X9) | I10: =IF(상품판매가산출!$B9="","",상품판매가산출!$R9) | J10: =IF(상품판매가산출!$B9="","",상품판매가산출!$U9) | K10: =IF(상품판매가산출!$B9="","",상품판매가산출!$V9)
B11: =IF(상품판매가산출!$B10="","",상품판매가산출!$B10) | C11: =IF(상품판매가산출!$B10="","",상품판매가산출!$C10) | D11: =IF(상품판매가산출!$B10="","",상품판매가산출!$I10) | E11: =IF(상품판매가산출!$B10="","",상품판매가산출!$H10) | F11: =IF(상품판매가산출!$B10="","",상품판매가산출!$L10) | G11: =IF(상품판매가산출!$B10="","",상품판매가산출!$O10) | H11: =IF(상품판매가산출!$B10="","",상품판매가산출!$X10) | I11: =IF(상품판매가산출!$B10="","",상품판매가산출!$R10) | J11: =IF(상품판매가산출!$B10="","",상품판매가산출!$U10) | K11: =IF(상품판매가산출!$B10="","",상품판매가산출!$V10)
B12: =IF(상품판매가산출!$B11="","",상품판매가산출!$B11) | C12: =IF(상품판매가산출!$B11="","",상품판매가산출!$C11) | D12: =IF(상품판매가산출!$B11="","",상품판매가산출!$I11) | E12: =IF(상품판매가산출!$B11="","",상품판매가산출!$H11) | F12: =IF(상품판매가산출!$B11="","",상품판매가산출!$L11) | G12: =IF(상품판매가산출!$B11="","",상품판매가산출!$O11) | H12: =IF(상품판매가산출!$B11="","",상품판매가산출!$X11) | I12: =IF(상품판매가산출!$B11="","",상품판매가산출!$R11) | J12: =IF(상품판매가산출!$B11="","",상품판매가산출!$U11) | K12: =IF(상품판매가산출!$B11="","",상품판매가산출!$V11)
B13: =IF(상품판매가산출!$B12="","",상품판매가산출!$B12) | C13: =IF(상품판매가산출!$B12="","",상품판매가산출!$C12) | D13: =IF(상품판매가산출!$B12="","",상품판매가산출!$I12) | E13: =IF(상품판매가산출!$B12="","",상품판매가산출!$H12) | F13: =IF(상품판매가산출!$B12="","",상품판매가산출!$L12) | G13: =IF(상품판매가산출!$B12="","",상품판매가산출!$O12) | H13: =IF(상품판매가산출!$B12="","",상품판매가산출!$X12) | I13: =IF(상품판매가산출!$B12="","",상품판매가산출!$R12) | J13: =IF(상품판매가산출!$B12="","",상품판매가산출!$U12) | K13: =IF(상품판매가산출!$B12="","",상품판매가산출!$V12)
B14: =IF(상품판매가산출!$B13="","",상품판매가산출!$B13) | C14: =IF(상품판매가산출!$B13="","",상품판매가산출!$C13) | D14: =IF(상품판매가산출!$B13="","",상품판매가산출!$I13) | E14: =IF(상품판매가산출!$B13="","",상품판매가산출!$H13) | F14: =IF(상품판매가산출!$B13="","",상품판매가산출!$L13) | G14: =IF(상품판매가산출!$B13="","",상품판매가산출!$O13) | H14: =IF(상품판매가산출!$B13="","",상품판매가산출!$X13) | I14: =IF(상품판매가산출!$B13="","",상품판매가산출!$R13) | J14: =IF(상품판매가산출!$B13="","",상품판매가산출!$U13) | K14: =IF(상품판매가산출!$B13="","",상품판매가산출!$V13)
B15: =IF(상품판매가산출!$B14="","",상품판매가산출!$B14) | C15: =IF(상품판매가산출!$B14="","",상품판매가산출!$C14) | D15: =IF(상품판매가산출!$B14="","",상품판매가산출!$I14) | E15: =IF(상품판매가산출!$B14="","",상품판매가산출!$H14) | F15: =IF(상품판매가산출!$B14="","",상품판매가산출!$L14) | G15: =IF(상품판매가산출!$B14="","",상품판매가산출!$O14) | H15: =IF(상품판매가산출!$B14="","",상품판매가산출!$X14) | I15: =IF(상품판매가산출!$B14="","",상품판매가산출!$R14) | J15: =IF(상품판매가산출!$B14="","",상품판매가산출!$U14) | K15: =IF(상품판매가산출!$B14="","",상품판매가산출!$V14)
B16: =IF(상품판매가산출!$B15="","",상품판매가산출!$B15) | C16: =IF(상품판매가산출!$B15="","",상품판매가산출!$C15) | D16: =IF(상품판매가산출!$B15="","",상품판매가산출!$I15) | E16: =IF(상품판매가산출!$B15="","",상품판매가산출!$H15) | F16: =IF(상품판매가산출!$B15="","",상품판매가산출!$L15) | G16: =IF(상품판매가산출!$B15="","",상품판매가산출!$O15) | H16: =IF(상품판매가산출!$B15="","",상품판매가산출!$X15) | I16: =IF(상품판매가산출!$B15="","",상품판매가산출!$R15) | J16: =IF(상품판매가산출!$B15="","",상품판매가산출!$U15) | K16: =IF(상품판매가산출!$B15="","",상품판매가산출!$V15)
B17: =IF(상품판매가산출!$B16="","",상품판매가산출!$B16) | C17: =IF(상품판매가산출!$B16="","",상품판매가산출!$C16) | D17: =IF(상품판매가산출!$B16="","",상품판매가산출!$I16) | E17: =IF(상품판매가산출!$B16="","",상품판매가산출!$H16) | F17: =IF(상품판매가산출!$B16="","",상품판매가산출!$L16) | G17: =IF(상품판매가산출!$B16="","",상품판매가산출!$O16) | H17: =IF(상품판매가산출!$B16="","",상품판매가산출!$X16) | I17: =IF(상품판매가산출!$B16="","",상품판매가산출!$R16) | J17: =IF(상품판매가산출!$B16="","",상품판매가산출!$U16) | K17: =IF(상품판매가산출!$B16="","",상품판매가산출!$V16)
B18: =IF(상품판매가산출!$B17="","",상품판매가산출!$B17) | C18: =IF(상품판매가산출!$B17="","",상품판매가산출!$C17) | D18: =IF(상품판매가산출!$B17="","",상품판매가산출!$I17) | E18: =IF(상품판매가산출!$B17="","",상품판매가산출!$H17) | F18: =IF(상품판매가산출!$B17="","",상품판매가산출!$L17) | G18: =IF(상품판매가산출!$B17="","",상품판매가산출!$O17) | H18: =IF(상품판매가산출!$B17="","",상품판매가산출!$X17) | I18: =IF(상품판매가산출!$B17="","",상품판매가산출!$R17) | J18: =IF(상품판매가산출!$B17="","",상품판매가산출!$U17) | K18: =IF(상품판매가산출!$B17="","",상품판매가산출!$V17)
... B26: =IF(상품판매가산출!$B25="","",상품판매가산출!$B25) | C26: =IF(상품판매가산출!$B25="","",상품판매가산출!$C25) | D26: =IF(상품판매가산출!$B25="","",상품판매가산출!$I25) | E26: =IF(상품판매가산출!$B25="","",상품판매가산출!$H25) | F26: =IF(상품판매가산출!$B25="","",상품판매가산출!$L25) | G26: =IF(상품판매가산출!$B25="","",상품판매가산출!$O25) | H26: =IF(상품판매가산출!$B25="","",상품판매가산출!$X25) | I26: =IF(상품판매가산출!$B25="","",상품판매가산출!$R25) | J26: =IF(상품판매가산출!$B25="","",상품판매가산출!$U25) | K26: =IF(상품판매가산출!$B25="","",상품판매가산출!$V25)
B27: 합계 | E27: =SUM(E7:E26) | I27: =IFERROR(SUM(K7:K26)/SUM(J7:J26),0) | J27: =SUM(J7:J26) | K27: =SUM(K7:K26)
B29: 이 시트는 상품판매가산출 시트를 그대로 비추기만 합니다. 값은 그쪽에서 고치세요.
B30: 최종 유통가는 영업이 입력한 값이며, 비어 있으면 기준 유통가가 그대로 적용된 것입니다.
B31: 소비자 판매가는 최종 유통가에 소비자 마진율을 얹은 값입니다. 품목별로 다르면 상품판매가산출 W열에 넣으세요.
B32: 매입단가는 부대비용까지 더한 개당 매입원가입니다.
B33: 매출 합계 · 영업이익 합계는 최종 유통가 기준이며 소비자 판매가는 반영되지 않습니다.
B34: 빈 줄을 감추려면 머리글의 필터에서 '(필드 값 없음)' 체크를 해제하세요.
B35: 최종 유통가가 BEP 가격보다 낮으면 빨갛게 표시됩니다 — 팔수록 손해입니다.

Sheet 사용안내
B2: 사용 안내
B4: 1. 매달 할 일 — 환율 갱신
B5: ① 서울외국환중개 월평균 매매기준율 페이지를 엽니다.
B6: http://www.smbs.biz/ExRate/MonAvgStdExRate.jsp
B7: ② 표에서 해당 월의 미국(USD)과 중국(CNY) 값을 확인합니다.
B8: ③ [월평균환율] 시트에 한 줄 추가합니다. 연월은 2026-08 처럼 텍스트로 입력하세요.
B9: ④ 끝입니다. 오늘이 9월이면 8월 값이 자동으로 잡힙니다.
B11: 2. 자동으로 받아오려면 — 파워쿼리 (Windows 엑셀)
B12: ① [데이터] 탭 → [데이터 가져오기] → [기타 원본에서] → [웹]
B13: ② 위 주소를 넣고 [확인] → 탐색 창에서 월평균 표를 고른 뒤 [데이터 변환]
B14: ③ 연월 · USD · CNY 열만 남기고, 연월을 텍스트로 바꾼 뒤 [닫기 및 로드]
B15: ④ 이후에는 [데이터] → [모두 새로 고침] 한 번이면 갱신됩니다.
... B62: · 이 파일의 환율과 품목은 모두 예시입니다. 실제 값으로 교체한 뒤 사용하세요.

Sheet 설정
B2: 수입자재 판매가 산출 — 설정
B3: 플로우텍 수입 → 태성정밀 공급 · 모든 금액 부가세 별도
B5: ■ 환율
B6: 기준 선택 | C6: 전월 평균 | D6: 전월 평균 / 당월 평균 / 직접 입력 중에서 고릅니다.
B7: 대상 월(날짜) | C7: =EOMONTH(TODAY(),IF($C$6="당월 평균",0,-1)) | D7: 오늘 날짜에서 자동 계산됩니다. 손대지 마세요.
B8: 적용 연월 | C8: =IF($C$6="직접 입력",$C$9,RIGHT("0000"&YEAR($C$7),4)&"-"&RIGHT("00"&MONTH($C$7),2)) | D8: 월평균환율 시트에서 이 연월을 찾아 환율을 가져옵니다.
B9: 직접 지정 연월 | C9: 2026-08 | D9: 기준 선택이 "직접 입력"일 때만 사용합니다. YYYY-MM 형식.
B11: 적용 USD / 원 | C11: =IF($C$6="직접 입력",$C$13,IFERROR(INDEX(월평균환율!$C$6:$C$101,MATCH($C$8,월평균환율!$B$6:$B$101,0)),$C$13)) | D11: 월평균환율 시트에 해당 연월이 없으면 아래 수동 환율을 씁니다.
B12: 적용 CNY / 원 | C12: =IF($C$6="직접 입력",$C$14,IFERROR(INDEX(월평균환율!$D$6:$D$101,MATCH($C$8,월평균환율!$B$6:$B$101,0)),$C$14))
B13: 수동 USD / 원 | C13: 1380 | D13: 예비값입니다. 실제 환율로 바꿔 주세요.
B14: 수동 CNY / 원 | C14: 190 | D14: 예비값입니다. 실제 환율로 바꿔 주세요.
B16: ■ 원가 · 이윤
B17: 부대비용률 | C17: 0.1 | D17: 운임 · 관세 · 통관수수료 · 창고/내륙운송 · 환리스크를 통으로 잡은 비율.
B18: 이윤율 | C18: 0.3 | D18: 품목별로 다르게 주려면 판매가산출 시트 G열에 개별 입력하세요.
B19: 계산 방식 | C19: 판매가 마진 | D19: "원가 가산" = 입고원가 × 1.30 · "판매가 마진" = 입고원가 ÷ 0.70
B20: 판매단가 절상 단위 | C20: 100 | D20: 1이면 반올림, 10/100/1000이면 그 단위로 올림 처리합니다.
B22: ■ 상품 판매가 (수입품 · 국내구매품 유통)
B23: 국내 부대비용률 | C23: 0 | D23: 국내구매품의 운반비 · 검수비 등. 없으면 0%.
B24: 판관비율 | C24: 0.087 | D24: 인건비 · 임차료 · 물류 · 판촉 등 판매관리비. 실제 손익계산서 비율로 바꾸세요.
B25: 영업이익률 | C25: 0.1 | D25: 기준 유통가에 얹을 목표 영업이익.
B26: 상품가 계산 방식 | C26: 매출 대비 | D26: "매출 대비" = 매입원가 ÷ (1 − 판관비율 − 영업이익률) · "원가 가산" = 매입원가 × (1+판관비율) × (1+영업이익률)
B27: 기준유통가 절상 단위 | C27: 100 | D27: 1이면 반올림, 100/1000이면 그 단위로 올림.
B28: 소비자 마진율 | C28: 0.2 | D28: 최종 유통가에 얹어 소비자 판매가를 만드는 비율. 품목별로 다르면 상품판매가산출 W열에 따로 넣으세요.
